Workbook
Name académico: '(info_t_d_c)'!$BC$3:$BC$199
Name analista_jr.: '(info_t_d_c)'!$AS$3:$AS$199
Name analista_sr.: '(info_t_d_c)'!$AR$3:$AR$199
Name ancho: '(cata_mp)'!$K$4:$K$15855
Name articulo: '(cata_mp)'!$C$4:$C$15855
Name bespoke: '(info_t_d_c)'!$BF$3:$BF$199
Name bespoke_y_desarrollo: '(info_t_d_c)'!$CA$3:$CA$199
Name bespoke_y_desarrollo_costo_de_gasto_indirecto: '(info_t_d_c)'!$FW$3:$FW$199
Name bespoke_y_desarrollo_costo_de_mano_de_obra: '(info_t_d_c)'!$FV$3:$FV$199
Name bespoke_y_desarrollo_costo_de_producto: '(info_t_d_c)'!$FU$3:$FU$199
Name bespoke_y_desarrollo_costos_y_precios: '(info_t_d_c)'!$FT$3:$FT$199
Name bespoke_y_desarrollo_precio_volumen_alto: '(info_t_d_c)'!$FX$3:$FX$199
Name bespoke_y_desarrollo_precio_volumen_bajo: '(info_t_d_c)'!$FZ$3:$FZ$199
Name bespoke_y_desarrollo_precio_volumen_intermedio: '(info_t_d_c)'!$FY$3:$FY$199
Name calendario: "Complemento 4"
Name cantidad_máxima_de_artículos: '(info_t_d_c)'!$AV$3:$AV$199
Name clave_comercial: '(cata_mp)'!$M$4:$M$15855
Name co_creación: '(info_t_d_c)'!$AG$3:$AG$22
Name co_creación_estratégica: '(info_t_d_c)'!$BZ$3:$BZ$199
Name co_creación_estratégica_costo_de_gasto_indirecto: '(info_t_d_c)'!$FP$3:$FP$199
Name co_creación_estratégica_costo_de_mano_de_obra: '(info_t_d_c)'!$FO$3:$FO$199
Name co_creación_estratégica_costo_de_producto: '(info_t_d_c)'!$FN$3:$FN$199
Name co_creación_estratégica_costos_y_precios: '(info_t_d_c)'!$FM$3:$FM$199
Name co_creación_estratégica_precio_volumen_alto: '(info_t_d_c)'!$FQ$3:$FQ$199
Name co_creación_estratégica_precio_volumen_bajo: '(info_t_d_c)'!$FS$3:$FS$199
Name co_creación_estratégica_precio_volumen_intermedio: '(info_t_d_c)'!$FR$3:$FR$199
Name comercial: '(info_t_d_c)'!$AY$3:$AY$199
Name compra_de_dólares_mxn: '(info_t_d_c)'!$CG$3:$CG$199
Name contabilidad_por_tipo_de_venta: '(info_t_d_c)'!$CF$3:$CF$10
Name corporativo: '(info_t_d_c)'!$AX$3:$AX$199
Name corto_contable: '(info_t_d_c)'!$H$3:$H$16
Name corto_de_tipo: '(info_t_d_c)'!$F$3:$F$11
Name corto_porcentaje: '(info_t_d_c)'!$I$3:$I$16
Name cos_fab: '(info_t_d_c)'!$I$6
Name cos_gas_ind: '(info_t_d_c)'!$I$5
Name cos_man_obr: '(info_t_d_c)'!$I$4
Name cos_mat: '(info_t_d_c)'!$I$3
Name costo_por_minuto: '(info_t_d_c)'!$AB$3:$AB$12
Name costo_última_compra: '(cata_mp)'!$I$4:$I$15855
Name costos_precios_y_descuentos: 'REG-DCC-IDP-032 (t_d_p)'!$D$28
Name departamento: '(info_t_d_c)'!$AE$3:$AE$34
Name des_com: '(info_t_d_c)'!$I$14
Name des_dir: '(info_t_d_c)'!$I$15
Name des_dis: '(info_t_d_c)'!$I$16
Name desarrollo: '(cata_mp)'!$L$4:$L$15855
Name descripción: '(cata_mp)'!$D$4:$D$15855
Name descripción_de_servicio_de_maquila: '(info_t_d_c)'!$AA$3:$AA$12
Name descripción_de_servicio_por_ganchos_en_tren_de_pintura: '(info_t_d_c)'!$AA$3:$AA$166
Name detalle_de_empaque_embalaje: '(info_t_d_c)'!$U$3:$U$13
Name detalle_de_entrega_trasporte_instalación: '(info_t_d_c)'!$X$3:$X$16
Name detalle_empaque_embalaje: 'REG-DCC-IDP-032 (t_d_p)'!$E$16
Name detalle_entrega_trasporte_instalación: 'REG-DCC-IDP-032 (t_d_p)'!$E$18
Name días_asignados: '(info_t_d_c)'!$AU$3:$AU$199
Name días_avilés_de_tabla: '(info_t_d_c)'!$L$3:$L$8
Name dificultad_de_task: '(info_t_d_c)'!$AT$3:$AT$199
Name dirección: '(info_t_d_c)'!$AC$3:$AC$11
Name dirección_co_creación_costo_de_gasto_indirecto: '(info_t_d_c)'!$GN$3:$GN$8
Name dirección_co_creación_costo_de_mano_de_obra: '(info_t_d_c)'!$GM$3:$GM$8
Name dirección_co_creación_costo_de_producto: '(info_t_d_c)'!$GL$3:$GL$8
Name dirección_co_creación_costos_y_precio: '(info_t_d_c)'!$GK$3:$GK$8

Sheet REG-DCC-IDP-032 (t_d_p)
C1: 46204 | D1: solicitud de tabla de comparación: | E1: {=MID(CELL("nombrearchivo"),FIND("[",CELL("nombrearchivo"))+1,FIND("]",CELL("nombrearchivo"))-FIND("[",CELL("nombrearchivo"))-1)} -> C-CO-516R Copete abatible de cabecera.xlsx
D3: fecha: | E3: solicita:
D4: 46248 | E4: =IFERROR(VLOOKUP($D$8,departamento:responsable,2,0),"") -> pedro_r.
D5: fecha_requerida: | E5: n°_de_días_propuestos
D6: 46248 | E6: =IFERROR(NETWORKDAYS.INTL(D4,D6,1),"") -> 1
D7: departamento: | E7: dificultad_de_task
D8: proyectos_vonhaucke | E8: =IFERROR(VLOOKUP($D$16,tipo_de_task:cantidad_máxima_de_artículos,5,0),"") -> intermedio_con_clave_desarrollo_información | H8: {=IFERROR((TRANSPOSE(INDIRECT($G$8))),"")}
D9: sector_de_venta | E9: diseño
D10: corporativo | E10: =IFERROR(VLOOKUP($D$20,tipo_de_línea:diseño,2,0),"") -> diseño_del_cliente
D11: tipo_de_venta | E11: moneda
D12: tradicional | E12: =IFERROR(VLOOKUP($D$12,tipo_de_venta:moneda,2,0),"") -> mxn
D13: n°_de_artículos | E13: contabilidad_por_tipo_de_venta
D14: 1 | E14: =IFERROR(VLOOKUP($D$12,tipo_de_venta:contabilidad_por_tipo_de_venta,4,0),"") -> venta_tradicional_costos_precios_y_descuentos
D15: tabla_requerida | E15: detalle_empaque_embalaje
D16: cotización_producto_vonhaucke(s) | E16: =IFERROR(VLOOKUP($D$24,nivel_emp___emb:detalle_de_empaque_embalaje,2,0),"") -> articulo_empacado_con_espuma_de_1⁄32"_+_cartón_+_película_elástica.
D17: mobiliario | E17: detalle_entrega_trasporte_instalación
D18: mobiliario_de_línea | E18: =IFERROR(VLOOKUP($D$26,nivel_logística:detalle_de_entrega_trasporte_instalación,2,0),"") -> al_cliente_en_vonhaucke_calle_4_no._80._sin_maniobras,_transporte,_instalación.
D19: línea
D20: línea_modificada
D21: =IFERROR(VLOOKUP($D$18,mobiliario:modelo_o_cliente,2,0),"modelo_o_cliente") -> modelo
D22: modulor
D23: tipo_empaque_embalaje
D24: emp_jgo_1_unitario_básico
D25: tipo_entrega_trasporte_instalación
D26: ent_1_cliente_vonhaucke
D27: costos_precios_y_descuentos
D28: standard_line_costos_precios_y_descuentos
D29: {=IFERROR((TRANSPOSE(INDIRECT($D$28))),"%")} -> standard_line_costo_de_producto | E29: standard_line_costo_de_mano_de_obra | F29: standard_line_costo_de_gasto_indirecto | G29: standard_line_precio_mínimo | H29: standard_line_precio_comercial | I29: standard_line_descuento_comercial | J29: standard_line_descuento_dirección | K29: standard_line_precio_distribuidor | L29: standard_line_descuento_distribuidor | M29: 0 | N29: 0 | O29: 0 | P29: 0 | Q29: 0 | R29: 0 | S29: 0 | T29: 0 | U29: 0 | V29: 0 | W29: 0 | X29: 0 | Y29: 0 | Z29: 0 | AA29: 0 | AB29: 0 | AC29: 0 | AD29: 0 | AE29: 0 | AF29: 0 | AG29: 0 | AH29: 0 | AI29: 0 | AJ29: 0 | AK29: 0 | AL29: 0 | AM29: 0 | AN29: 0 | AO29: 0 | AP29: 0 | AQ29: 0 | AR29: 0 | AS29: 0 | AT29: 0 | AU29: 0 | AV29: 0 | AW29: 0 | AX29: 0 | AY29: 0 | AZ29: 0 | BA29: 0 | BB29: 0 | BC29: 0 | BD29: 0 | BE29: 0 | BF29: 0 | BG29: 0 | BH29: 0 | BI29: 0 | BJ29: 0 | BK29: 0 | BL29: 0 | BM29: 0 | BN29: 0 | BO29: 0 | BP29: 0 | BQ29: 0 | BR29: 0 | BS29: 0 | BT29: 0 | BU29: 0 | BV29: 0 | BW29: 0 | BX29: 0 | BY29: 0 | BZ29: 0 | CA29: 0 | CB29: 0 | CC29: 0 | CD29: 0 | CE29: 0 | CF29: 0 | CG29: 0 | CH29: 0 | CI29: 0 | CJ29: 0 | CK29: 0 | CL29: 0 | CM29: 0 | CN29: 0 | CO29: 0 | CP29: 0 | CQ29: 0 | CR29: 0 | CS29: 0 | CT29: 0 | CU29: 0 | CV29: 0 | CW29: 0 | CX29: 0 | CY29: 0 | CZ29: 0 | DA29: 0 | DB29: 0 | DC29: 0 | DD29: 0 | DE29: 0 | DF29: 0 | DG29: 0 | DH29: 0 | DI29: 0 | DJ29: 0 | DK29: 0 | DL29: 0 | DM29: 0 | DN29: 0 | DO29: 0 | DP29: 0 | DQ29: 0 | DR29: 0 | DS29: 0 | DT29: 0 | DU29: 0 | DV29: 0 | DW29: 0 | DX29: 0 | DY29: 0 | DZ29: 0 | EA29: 0 | EB29: 0 | EC29: 0 | ED29: 0 | EE29: 0 | EF29: 0 | EG29: 0 | EH29: 0 | EI29: 0 | EJ29: 0 | EK29: 0 | EL29: 0 | EM29: 0 | EN29: 0 | EO29: 0 | EP29: 0 | EQ29: 0 | ER29: 0 | ES29: 0 | ET29: 0 | EU29: 0 | EV29: 0 | EW29: 0 | EX29: 0 | EY29: 0 | EZ29: 0 | FA29: 0 | FB29: 0 | FC29: 0 | FD29: 0 | FE29: 0 | FF29: 0 | FG29: 0 | FH29: 0 | FI29: 0 | FJ29: 0 | FK29: 0 | FL29: 0 | FM29: 0 | FN29: 0 | FO29: 0 | FP29: 0 | FQ29: 0 | FR29: 0 | FS29: 0 | FT29: 0 | FU29: 0 | FV29: 0 | FW29: 0 | FX29: 0 | FY29: 0 | FZ29: 0 | GA29: 0 | GB29: 0 | GC29: 0 | GD29: 0 | GE29: 0 | GF29: 0 | GG29: 0 | GH29: 0 | GI29: 0 | GJ29: 0 | GK29: 0 | GL29: 0 | GM29: 0 | GN29: 0 | GO29: 0 | GP29: 0 | GQ29: 0 | GR29: 0
D30: {=IFERROR(INDIRECT(TRANSPOSE(D29)),"%")} -> standard_line_mueble_fabricado | E30: {=IFERROR(INDIRECT(TRANSPOSE(E29)),"%")} -> 0.2 | F30: {=IFERROR(INDIRECT(TRANSPOSE(F29)),"%")} -> 3 | G30: {=IFERROR(INDIRECT(TRANSPOSE(G29)),"%")} -> 1.45 | H30: {=IFERROR(INDIRECT(TRANSPOSE(H29)),"%")} -> 0.7 | I30: {=IFERROR(INDIRECT(TRANSPOSE(I29)),"%")} -> 0.1 | J30: {=IFERROR(INDIRECT(TRANSPOSE(J29)),"%")} -> #VALUE! | K30: {=IFERROR(INDIRECT(TRANSPOSE(K29)),"%")} -> #VALUE! | L30: {=IFERROR(INDIRECT(TRANSPOSE(L29)),"%")} -> #VALUE!
D31: standard_line_componente_fabricado | E31: 0.15 | F31: 3 | G31: 1.45 | H31: 0.7 | I31: 0.1 | J31: {=IFERROR(INDIRECT(TRANSPOSE(J30)),"%")} -> % | K31: {=IFERROR(INDIRECT(TRANSPOSE(K30)),"%")} -> % | L31: {=IFERROR(INDIRECT(TRANSPOSE(L30)),"%")} -> %
D32: standard_line_mueble_compra_venta | E32: 0.01 | F32: 0.05 | G32: 1.25 | H32: 0.7 | I32: 0.1 | J32: {=IFERROR(INDIRECT(TRANSPOSE(J31)),"%")} -> % | K32: {=IFERROR(INDIRECT(TRANSPOSE(K31)),"%")} -> % | L32: {=IFERROR(INDIRECT(TRANSPOSE(L31)),"%")} -> %
D33: standard_line_componente_compra_venta | E33: 0.05 | F33: 0.05 | G33: 1.25 | H33: 0.7 | I33: 0.1 | J33: {=IFERROR(INDIRECT(TRANSPOSE(J32)),"%")} -> % | K33: {=IFERROR(INDIRECT(TRANSPOSE(K32)),"%")} -> % | L33: {=IFERROR(INDIRECT(TRANSPOSE(L32)),"%")} -> %
D34: standard_line_accesorio_compra_venta | E34: 0.01 | F34: 0.05 | G34: 1.25 | H34: 0.7 | I34: 0.1 | J34: {=IFERROR(INDIRECT(TRANSPOSE(J33)),"%")} -> % | K34: {=IFERROR(INDIRECT(TRANSPOSE(K33)),"%")} -> % | L34: {=IFERROR(INDIRECT(TRANSPOSE(L33)),"%")} -> %
D35: standard_line_servicio_directo | E35: 0.1 | F35: 2.75 | G35: 1.2 | H35: 0 | I35: 1.2 | J35: {=IFERROR(INDIRECT(TRANSPOSE(J34)),"%")} -> % | K35: {=IFERROR(INDIRECT(TRANSPOSE(K34)),"%")} -> % | L35: {=IFERROR(INDIRECT(TRANSPOSE(L34)),"%")} -> %
D36: 0 | E36: 0 | F36: 0 | G36: 0 | H36: 0 | I36: 0 | J36: {=IFERROR(INDIRECT(TRANSPOSE(J35)),"%")} -> % | K36: {=IFERROR(INDIRECT(TRANSPOSE(K35)),"%")} -> % | L36: {=IFERROR(INDIRECT(TRANSPOSE(L35)),"%")} -> %
D37: 0 | E37: 0 | F37: 0 | G37: 0 | H37: 0 | I37: 0 | J37: {=IFERROR(INDIRECT(TRANSPOSE(J36)),"%")} -> % | K37: {=IFERROR(INDIRECT(TRANSPOSE(K36)),"%")} -> % | L37: {=IFERROR(INDIRECT(TRANSPOSE(L36)),"%")} -> %
D38: 0 | E38: 0 | F38: 0 | G38: 0 | H38: 0 | I38: 0 | J38: {=IFERROR(INDIRECT(TRANSPOSE(J37)),"%")} -> % | K38: {=IFERROR(INDIRECT(TRANSPOSE(K37)),"%")} -> % | L38: {=IFERROR(INDIRECT(TRANSPOSE(L37)),"%")} -> %
D39: 0 | E39: 0 | F39: 0 | G39: 0 | H39: 0 | I39: 0 | J39: {=IFERROR(INDIRECT(TRANSPOSE(J38)),"%")} -> % | K39: {=IFERROR(INDIRECT(TRANSPOSE(K38)),"%")} -> % | L39: {=IFERROR(INDIRECT(TRANSPOSE(L38)),"%")} -> %
D40: 0 | E40: 0 | F40: 0 | G40: 0 | H40: 0 | I40: 0 | J40: {=IFERROR(INDIRECT(TRANSPOSE(J39)),"%")} -> % | K40: {=IFERROR(INDIRECT(TRANSPOSE(K39)),"%")} -> % | L40: {=IFERROR(INDIRECT(TRANSPOSE(L39)),"%")} -> %
D41: 0 | E41: 0 | F41: 0 | G41: 0 | H41: 0 | I41: 0 | J41: {=IFERROR(INDIRECT(TRANSPOSE(J40)),"%")} -> % | K41: {=IFERROR(INDIRECT(TRANSPOSE(K40)),"%")} -> % | L41: {=IFERROR(INDIRECT(TRANSPOSE(L40)),"%")} -> %
...

Sheet REG-DCC-IDP-031 (T_d_C) 
C1: estimaciones y análisis de costos | L1: Registro | O1: REG-DCC-IDP-031
C2: tabla de comparación | L2: Tabla de comparación | O2: Revision: 9.0 | P2: Version: 4.0
C3: {=MID(CELL("nombrearchivo"),FIND("[",CELL("nombrearchivo"))+1,FIND("]",CELL("nombrearchivo"))-FIND("[",CELL("nombrearchivo"))-1)} -> C-CO-516R Copete abatible de cabecera.xlsx | L3: Asociado a: Cláusula 8.2 Requisitos para los productos y servicios; Procedimiento de estimaciones y costos, Manual del Sistema de Gestión de la Calidad. | O3: Página: 1 de 1
C5: Informacion de solicitud: | P5: fecha:
C6: solicita: | P6: 46280
D7: =solicita -> pedro_r.
C8: fecha_requerida:
D9: =fecha_requerida -> 46248
C10: tipo de tabla:
D11: =tabla_requerida -> cotización_producto_vonhaucke(s)
C12: contabilidad de tabla:
D13: =costos_precios_y_descuentos -> standard_line_costos_precios_y_descuentos
C14: tipo de ventta:
D15: ='REG-DCC-IDP-032 (t_d_p)'!E14 -> venta_tradicional_costos_precios_y_descuentos
C16: tipo de empaque y/o embalaje incluyen:
D17: =tipo_empaque_embalaje -> emp_jgo_1_unitario_básico
C18: tipo de entrega y/o instalacion incluye: | J18: 0.15 | K18: 0.05 | M18: 1.25
D19: =tipo_entrega_trasporte_instalación -> ent_1_cliente_vonhaucke | J19: 0.2 | K19: 3 | M19: 1.55 | N19: 0.7 | O19: 0.42
D21: id_nº | E21: clave | F21: imagen | G21: descripcion | H21: cantidad | I21: $_cos_mat | J21: $_cos_man_obr | K21: $_cos_gas_ind | L21: $_cos_fab | M21: precio_mínimo | N21: precio_lista | O21: precio_2
D22: id_01 | E22: Copete abatible de 1000 x 900 x 58 mm. | G22: Copete abatible de 1000 x 900 x 58 mm, plegado. Fabricado en: Marcos y brazos en perfil cuadrado de 1" cal 18 armados a 45°. Bisagra metálica tipo libro de 2 x 2 para pliegue de marcos y de herrajes. Herrajes de ajuste fabricado en lámina cal 14, hoja de 4x10. Marcos de fabricados a partir de baguetas de lámina cal 18, hoja 4 x 10. Tuerca hexagonal galvanizada de para tornillo de 1/4". Tornillo perilla estrella ø 1/4" x 2 1/2” en plástico color negro - "PEE14212" Acabado en electropintura Charcoal op 118. | H22: De 750 a 1,000 | I22: =id_01_costo_total -> 460.57 | J22: =I22*$J$19 -> 92.11 | K22: =J22*$K$19 -> 276.33 | L22: =SUM(I22:K22) -> 829.01 | M22: =ROUNDUP((L22*$M$19),-1) -> 1290 | N22: =ROUNDUP((M22/0.699),-1) -> 1850 | O22: =ROUNDUP((M22/$O$19),-1) -> 3080
D23: id_02 | I23: =id_02_costo_total -> 0 | J23: =I23*$J$19 -> 0 | K23: =J23*$K$19 -> 0 | L23: =SUM(I23:K23) -> 0 | M23: =ROUNDUP((L23*$M$19),-1) -> 0 | N23: =ROUNDUP((M23/0.699),-1) -> 0 | O23: =ROUNDUP((M23/$O$19),-1) -> 0
D24: id_03 | I24: =id_03_costo_total -> 0 | J24: =I24*$J$18 -> 0 | K24: =J24*$K$19 -> 0 | L24: =SUM(I24:K24) -> 0 | M24: =ROUNDUP((L24*$M$19),-1) -> 0 | N24: =ROUNDUP((M24/0.699),-1) -> 0 | O24: =ROUNDUP((M24/$O$19),-1) -> 0
D25: id_04 | I25: =id_04_costo_total -> 0 | J25: =I25*$J$18 -> 0 | K25: =J25*$K$19 -> 0 | L25: =SUM(I25:K25) -> 0 | M25: =ROUNDUP((L25*$M$19),-1) -> 0 | N25: =ROUNDUP((M25/0.699),-1) -> 0 | O25: =ROUNDUP((M25/$O$19),-1) -> 0
D26: id_05 | I26: =id_05_costo_total -> 0 | J26: =I26*$J$18 -> 0 | K26: =J26*$K$19 -> 0 | L26: =SUM(I26:K26) -> 0 | M26: =ROUNDUP((L26*$M$19),-1) -> 0 | N26: =ROUNDUP((M26/0.699),-1) -> 0 | O26: =ROUNDUP((M26/$O$19),-1) -> 0
D27: id_06 | I27: =id_06_costo_total -> 0 | J27: =I27*$J$19 -> 0 | K27: =J27*$K$19 -> 0 | L27: =SUM(I27:K27) -> 0 | M27: =ROUNDUP((L27*$M$19),-1) -> 0 | N27: =ROUNDUP((M27/0.699),-1) -> 0 | O27: =ROUNDUP((M27/$O$19),-1) -> 0
D28: id_07 | I28: =id_07_costo_total -> 0 | J28: =I28*$J$19 -> 0 | K28: =J28*$K$19 -> 0 | L28: =SUM(I28:K28) -> 0 | M28: =ROUNDUP((L28*$M$19),-1) -> 0 | N28: =ROUNDUP((M28/0.699),-1) -> 0 | O28: =ROUNDUP((M28/$O$19),-1) -> 0
D29: id_08 | I29: =id_08_costo_total -> 0 | J29: =I29*$J$19 -> 0 | K29: =J29*$K$19 -> 0 | L29: =SUM(I29:K29) -> 0 | M29: =ROUNDUP((L29*$M$19),-1) -> 0 | N29: =ROUNDUP((M29/0.699),-1) -> 0 | O29: =ROUNDUP((M29/$O$19),-1) -> 0
D30: id_09 | I30: =id_09_costo_total -> 0 | J30: =I30*$J$19 -> 0 | K30: =J30*$K$19 -> 0 | L30: =SUM(I30:K30) -> 0 | M30: =ROUNDUP((L30*$M$19),-1) -> 0 | N30: =ROUNDUP((M30/0.699),-1) -> 0 | O30: =ROUNDUP((M30/$O$19),-1) -> 0
D31: id_10 | I31: =id_10_costo_total -> 0 | J31: =I31*$J$19 -> 0 | K31: =J31*$K$19 -> 0 | L31: =SUM(I31:K31) -> 0 | M31: =ROUNDUP((L31*$M$19),-1) -> 0 | N31: =ROUNDUP((M31/0.699),-1) -> 0 | O31: =ROUNDUP((M31/$O$19),-1) -> 0
D34: Departamento de estimaciones y costos
C36: * | D36: fabricación a nuestra capacidad de proceso
C37: * | D37: tolerancias en dimensión general + - 5mm y en cuota crítica + - 3mm.
C38: * | D38: nivel de empaque / emp_jgo_1_unitario_basico
C39: * | D39: nivel de maneobra / transporte / entrega / instalacion
C40: * | D40: moneda en $-MXP
C41: * | D41: precios sin IVA
C42: * | D42: costo de tabla validos por 15 días
C43: * | D43: Analista/ Angel Adaya

Sheet  (Explo_MP)
D3: ='REG-DCC-IDP-032 (t_d_p)'!D30 -> standard_line_mueble_fabricado | E3: ='REG-DCC-IDP-032 (t_d_p)'!D29 -> standard_line_costo_de_producto | F3: ='REG-DCC-IDP-032 (t_d_p)'!F29 -> standard_line_costo_de_gasto_indirecto | G3: ='REG-DCC-IDP-032 (t_d_p)'!J3 -> 0 | H3: ='REG-DCC-IDP-032 (t_d_p)'!K3 -> 0 | I3: ='REG-DCC-IDP-032 (t_d_p)'!L3 -> 0 | J3: ='REG-DCC-IDP-032 (t_d_p)'!M3 -> 0 | K3: ='REG-DCC-IDP-032 (t_d_p)'!#REF! -> #REF! | L3: ='REG-DCC-IDP-032 (t_d_p)'!#REF! -> #REF! | M3: ='REG-DCC-IDP-032 (t_d_p)'!#REF! -> #REF! | P3: ='REG-DCC-IDP-031 (T_d_C) '!D22 -> id_01
D4: ='REG-DCC-IDP-032 (t_d_p)'!D31 -> standard_line_componente_fabricado | E4: ='REG-DCC-IDP-032 (t_d_p)'!#REF! -> #REF! | F4: ='REG-DCC-IDP-032 (t_d_p)'!F30 -> 3 | G4: ='REG-DCC-IDP-032 (t_d_p)'!J4 -> 0 | H4: ='REG-DCC-IDP-032 (t_d_p)'!K4 -> 0 | I4: ='REG-DCC-IDP-032 (t_d_p)'!L4 -> 0 | J4: ='REG-DCC-IDP-032 (t_d_p)'!M4 -> 0 | K4: ='REG-DCC-IDP-032 (t_d_p)'!#REF! -> #REF! | L4: ='REG-DCC-IDP-032 (t_d_p)'!#REF! -> #REF! | M4: ='REG-DCC-IDP-032 (t_d_p)'!#REF! -> #REF! | R4: familia_de_operación | S4: articulo | T4: descripción | U4: opción | V4: opción_descripción | W4: unidad | X4: fecha_última_compra | Y4: costo_última_compra | Z4: consumo_unitaruio | AA4: costo_unitario
D5: ='REG-DCC-IDP-032 (t_d_p)'!D32 -> standard_line_mueble_compra_venta | E5: ='REG-DCC-IDP-032 (t_d_p)'!#REF! -> #REF! | F5: ='REG-DCC-IDP-032 (t_d_p)'!F31 -> 3 | G5: ='REG-DCC-IDP-032 (t_d_p)'!J5 -> 0 | H5: ='REG-DCC-IDP-032 (t_d_p)'!K5 -> 0 | I5: ='REG-DCC-IDP-032 (t_d_p)'!L5 -> 0 | J5: ='REG-DCC-IDP-032 (t_d_p)'!M5 -> 0 | K5: ='REG-DCC-IDP-032 (t_d_p)'!#REF! -> #REF! | L5: ='REG-DCC-IDP-032 (t_d_p)'!#REF! -> #REF! | M5: ='REG-DCC-IDP-032 (t_d_p)'!#REF! -> #REF! | T5: ='REG-DCC-IDP-031 (T_d_C) '!E22 -> Copete abatible de 1000 x 900 x 58 mm.
S6: MVLSTU01080401 | T6: =IFERROR(VLOOKUP(S6,'(cata_mp)'!C14:I16417,2,FALSE)," ") -> TUBULAR INDUSTRIAL CUADRADO 1" CALIBRE 18 PIEZA DE 6000 mm - TC181 | U6: - | V6: =IFERROR(INDEX(opción_descripción,MATCH(' (Explo_MP)'!$U6,opción,0))," ") -> Sin Opc. | W6: =IFERROR(VLOOKUP(S6,'(cata_mp)'!C29:I16432,5,FALSE)," ") -> pieza | X6: {=IFERROR(INDEX('(cata_mp)'!H28:H16431,MATCH(' (Explo_MP)'!S6&' (Explo_MP)'!U6,'(cata_mp)'!C28:C16431&'(cata_mp)'!E28:E16431,0)), " ")} -> 46121 | Y6: {=IFERROR(INDEX('(cata_mp)'!I:I,MATCH(' (Explo_MP)'!S6&' (Explo_MP)'!U6,'(cata_mp)'!C:C&'(cata_mp)'!E:E,0)),"$ 0")} -> 122.41 | Z6: 1.5 | AA6: =Y6*Z6 -> 183.62
T7: Bisagra libro soldable 2″ x 2″ | U7: - | V7: =IFERROR(INDEX(opción_descripción,MATCH(' (Explo_MP)'!$U7,opción,0))," ") -> Sin Opc. | W7: =IFERROR(VLOOKUP(S7,'(cata_mp)'!C30:I16433,5,FALSE)," ") | X7: {=IFERROR(INDEX('(cata_mp)'!H29:H16432,MATCH(' (Explo_MP)'!S7&' (Explo_MP)'!U7,'(cata_mp)'!C29:C16432&'(cata_mp)'!E29:E16432,0)), " ")} | Y7: 11.01 | Z7: 6 | AA7: =Y7*Z7 -> 66.06
S8: MVLSLA05270202 | T8: =IFERROR(VLOOKUP(S8,'(cata_mp)'!C16:I16419,2,FALSE)," ") -> LAMINA NEGRA HOJA 4 X 10 CALIBRE 14 ACERO 1008 - ""LN14410""" | U8: - | V8: =IFERROR(INDEX(opción_descripción,MATCH(' (Explo_MP)'!$U8,opción,0))," ") -> Sin Opc. | W8: =IFERROR(VLOOKUP(S8,'(cata_mp)'!C31:I16434,5,FALSE)," ") -> Hoja | X8: {=IFERROR(INDEX('(cata_mp)'!H30:H16433,MATCH(' (Explo_MP)'!S8&' (Explo_MP)'!U8,'(cata_mp)'!C30:C16433&'(cata_mp)'!E30:E16433,0)), " ")} -> 45868 | Y8: {=IFERROR(INDEX('(cata_mp)'!I:I,MATCH(' (Explo_MP)'!S8&' (Explo_MP)'!U8,'(cata_mp)'!C:C&'(cata_mp)'!E:E,0)),"$ 0")} -> 1125.4 | Z8: 0.02 | AA8: =Y8*Z8 -> 22.51
S9: MVLSLA05270402 | T9: =IFERROR(VLOOKUP(S9,'(cata_mp)'!C17:I16420,2,FALSE)," ") -> LAMINA NEGRA HOJA 4 X 10 CALIBRE 18 ACERO 1008 - ""LN18410""" | U9: - | V9: =IFERROR(INDEX(opción_descripción,MATCH(' (Explo_MP)'!$U9,opción,0))," ") -> Sin Opc. | W9: =IFERROR(VLOOKUP(S9,'(cata_mp)'!C32:I16435,5,FALSE)," ") -> Hoja | X9: {=IFERROR(INDEX('(cata_mp)'!H31:H16434,MATCH(' (Explo_MP)'!S9&' (Explo_MP)'!U9,'(cata_mp)'!C31:C16434&'(cata_mp)'!E31:E16434,0)), " ")} -> 45947 | Y9: {=IFERROR(INDEX('(cata_mp)'!I:I,MATCH(' (Explo_MP)'!S9&' (Explo_MP)'!U9,'(cata_mp)'!C:C&'(cata_mp)'!E:E,0)),"$ 0")} -> 696.71 | Z9: 0.02 | AA9: =Y9*Z9 -> 13.93
S10: MVLUTO34160016 | T10: =IFERROR(VLOOKUP(S10,'(cata_mp)'!C18:I16421,2,FALSE)," ") -> TORNILLO PERILLA ESTRELLA Ø 1/4" X 2 1/2" EN PLASTICO COLOR NEGRO - "PEE14212" | U10: - | V10: =IFERROR(INDEX(opción_descripción,MATCH(' (Explo_MP)'!$U10,opción,0))," ") -> Sin Opc. | W10: =IFERROR(VLOOKUP(S10,'(cata_mp)'!C33:I16436,5,FALSE)," ") -> pieza | X10: {=IFERROR(INDEX('(cata_mp)'!H32:H16435,MATCH(' (Explo_MP)'!S10&' (Explo_MP)'!U10,'(cata_mp)'!C32:C16435&'(cata_mp)'!E32:E16435,0)), " ")} -> 42461 | Y10: {=IFERROR(INDEX('(cata_mp)'!I:I,MATCH(' (Explo_MP)'!S10&' (Explo_MP)'!U10,'(cata_mp)'!C:C&'(cata_mp)'!E:E,0)),"$ 0")} -> 10 | Z10: 10 | AA10: =Y10*Z10 -> 100
S11: MVLUTU22520002 | T11: =IFERROR(VLOOKUP(S11,'(cata_mp)'!C19:I16422,2,FALSE)," ") -> TUERCA HEXAGONAL Ø1/4" GALVANIZADO -- TU14HE | U11: - | V11: =IFERROR(INDEX(opción_descripción,MATCH(' (Explo_MP)'!$U11,opción,0))," ") -> Sin Opc. | W11: =IFERROR(VLOOKUP(S11,'(cata_mp)'!C34:I16437,5,FALSE)," ") -> pieza | X11: {=IFERROR(INDEX('(cata_mp)'!H33:H16436,MATCH(' (Explo_MP)'!S11&' (Explo_MP)'!U11,'(cata_mp)'!C33:C16436&'(cata_mp)'!E33:E16436,0)), " ")} -> 46042 | Y11: {=IFERROR(INDEX('(cata_mp)'!I:I,MATCH(' (Explo_MP)'!S11&' (Explo_MP)'!U11,'(cata_mp)'!C:C&'(cata_mp)'!E:E,0)),"$ 0")} -> 0.22 | Z11: 12 | AA11: =Y11*Z11 -> 2.64
S12: MVLQPP00000000 | T12: =IFERROR(VLOOKUP(S12,'(cata_mp)'!C16:I16419,2,FALSE)," ") -> PINTURA EN POLVO - ""PPH""" | U12: a118 | V12: =IFERROR(INDEX(opción_descripción,MATCH(' (Explo_MP)'!$U12,opción,0))," ") -> COLOR METAL CHARCOAL | W12: =IFERROR(VLOOKUP(S12,'(cata_mp)'!C31:I16434,5,FALSE)," ") -> Kg | X12: {=IFERROR(INDEX('(cata_mp)'!H30:H16433,MATCH(' (Explo_MP)'!S12&' (Explo_MP)'!U12,'(cata_mp)'!C30:C16433&'(cata_mp)'!E30:E16433,0)), " ")} -> 46107 | Y12: {=IFERROR(INDEX('(cata_mp)'!I:I,MATCH(' (Explo_MP)'!S12&' (Explo_MP)'!U12,'(cata_mp)'!C:C&'(cata_mp)'!E:E,0)),"$ 0")} -> 181.99 | Z12: =0.32+0.01 -> 0.33 | AA12: =Y12*Z12 -> 60.06
T13: emp_jgo_1_unitario_basico | U13: - | V13: =IFERROR(INDEX(opción_descripción,MATCH(' (Explo_MP)'!$U13,opción,0))," ") -> Sin Opc. | W13: =IFERROR(VLOOKUP(S13,'(cata_mp)'!C32:I16435,5,FALSE)," ") | X13: {=IFERROR(INDEX('(cata_mp)'!H31:H16434,MATCH(' (Explo_MP)'!S13&' (Explo_MP)'!U13,'(cata_mp)'!C31:C16434&'(cata_mp)'!E31:E16434,0)), " ")} | Y13: 225.99 | Z13: =1*0.9*0.058 -> 0.052 | AA13: =Y13*Z13 -> 11.75
T14: =IFERROR(VLOOKUP(S14,'(cata_mp)'!C20:I16423,2,FALSE)," ") | U14: - | V14: =IFERROR(INDEX(opción_descripción,MATCH(' (Explo_MP)'!$U14,opción,0))," ") -> Sin Opc. | W14: =IFERROR(VLOOKUP(S14,'(cata_mp)'!C35:I16438,5,FALSE)," ") | X14: {=IFERROR(INDEX('(cata_mp)'!H34:H16437,MATCH(' (Explo_MP)'!S14&' (Explo_MP)'!U14,'(cata_mp)'!C34:C16437&'(cata_mp)'!E34:E16437,0)), " ")} | Y14: {=IFERROR(INDEX('(cata_mp)'!I:I,MATCH(' (Explo_MP)'!S14&' (Explo_MP)'!U14,'(cata_mp)'!C:C&'(cata_mp)'!E:E,0)),"$ 0")} -> $ 0 | AA14: =Y14*Z14 -> 0
Y15: =P3 -> id_01 | Z15: =P3&" costo_total:" -> id_01 costo_total: | AA15: =+SUM(AA6:AA14) -> 460.57
P19: ='REG-DCC-IDP-031 (T_d_C) '!D23 -> id_02
R20: familia_de_operación | S20: articulo | T20: descripción | U20: opción | V20: opción_descripción | W20: unidad | X20: fecha_última_compra | Y20: costo_última_compra | Z20: consumo_unitaruio | AA20: costo_unitario
T21: ='REG-DCC-IDP-031 (T_d_C) '!E23 -> 0
T22: =IFERROR(VLOOKUP(S22,'(cata_mp)'!C37:I16440,2,FALSE)," ") | U22: - | V22: =IFERROR(INDEX(opción_descripción,MATCH(' (Explo_MP)'!$U22,opción,0))," ") -> Sin Opc. | W22: =IFERROR(VLOOKUP(S22,'(cata_mp)'!C40:I16443,5,FALSE)," ") | X22: {=IFERROR(INDEX('(cata_mp)'!H39:H16442,MATCH(' (Explo_MP)'!S22&' (Explo_MP)'!U22,'(cata_mp)'!C39:C16442&'(cata_mp)'!E39:E16442,0)), " ")} | Y22: {=IFERROR(INDEX('(cata_mp)'!I:I,MATCH(' (Explo_MP)'!S22&' (Explo_MP)'!U22,'(cata_mp)'!C:C&'(cata_mp)'!E:E,0)),"$ 0")} -> $ 0 | AA22: =Y22*Z22 -> 0
T23: =IFERROR(VLOOKUP(S23,'(cata_mp)'!C38:I16441,2,FALSE)," ") | U23: - | V23: =IFERROR(INDEX(opción_descripción,MATCH(' (Explo_MP)'!$U23,opción,0))," ") -> Sin Opc. | W23: =IFERROR(VLOOKUP(S23,'(cata_mp)'!C41:I16444,5,FALSE)," ") | X23: {=IFERROR(INDEX('(cata_mp)'!H40:H16443,MATCH(' (Explo_MP)'!S23&' (Explo_MP)'!U23,'(cata_mp)'!C40:C16443&'(cata_mp)'!E40:E16443,0)), " ")} | Y23: {=IFERROR(INDEX('(cata_mp)'!I:I,MATCH(' (Explo_MP)'!S23&' (Explo_MP)'!U23,'(cata_mp)'!C:C&'(cata_mp)'!E:E,0)),"$ 0")} -> $ 0 | AA23: =Y23*Z23 -> 0
T24: =IFERROR(VLOOKUP(S24,'(cata_mp)'!C39:I16442,2,FALSE)," ") | U24: - | V24: =IFERROR(INDEX(opción_descripción,MATCH(' (Explo_MP)'!$U24,opción,0))," ") -> Sin Opc. | W24: =IFERROR(VLOOKUP(S24,'(cata_mp)'!C42:I16445,5,FALSE)," ") | X24: {=IFERROR(INDEX('(cata_mp)'!H41:H16444,MATCH(' (Explo_MP)'!S24&' (Explo_MP)'!U24,'(cata_mp)'!C41:C16444&'(cata_mp)'!E41:E16444,0)), " ")} | Y24: {=IFERROR(INDEX('(cata_mp)'!I:I,MATCH(' (Explo_MP)'!S24&' (Explo_MP)'!U24,'(cata_mp)'!C:C&'(cata_mp)'!E:E,0)),"$ 0")} -> $ 0 | AA24: =Y24*Z24 -> 0
T25: =IFERROR(VLOOKUP(S25,'(cata_mp)'!C40:I16443,2,FALSE)," ") | U25: - | V25: =IFERROR(INDEX(opción_descripción,MATCH(' (Explo_MP)'!$U25,opción,0))," ") -> Sin Opc. | W25: =IFERROR(VLOOKUP(S25,'(cata_mp)'!C43:I16446,5,FALSE)," ") | X25: {=IFERROR(INDEX('(cata_mp)'!H42:H16445,MATCH(' (Explo_MP)'!S25&' (Explo_MP)'!U25,'(cata_mp)'!C42:C16445&'(cata_mp)'!E42:E16445,0)), " ")} | Y25: {=IFERROR(INDEX('(cata_mp)'!I:I,MATCH(' (Explo_MP)'!S25&' (Explo_MP)'!U25,'(cata_mp)'!C:C&'(cata_mp)'!E:E,0)),"$ 0")} -> $ 0 | AA25: =Y25*Z25 -> 0
T26: =IFERROR(VLOOKUP(S26,'(cata_mp)'!C41:I16444,2,FALSE)," ") | U26: - | V26: =IFERROR(INDEX(opción_descripción,MATCH(' (Explo_MP)'!$U26,opción,0))," ") -> Sin Opc. | W26: =IFERROR(VLOOKUP(S26,'(cata_mp)'!C44:I16447,5,FALSE)," ") | X26: {=IFERROR(INDEX('(cata_mp)'!H43:H16446,MATCH(' (Explo_MP)'!S26&' (Explo_MP)'!U26,'(cata_mp)'!C43:C16446&'(cata_mp)'!E43:E16446,0)), " ")} | Y26: {=IFERROR(INDEX('(cata_mp)'!I:I,MATCH(' (Explo_MP)'!S26&' (Explo_MP)'!U26,'(cata_mp)'!C:C&'(cata_mp)'!E:E,0)),"$ 0")} -> $ 0 | AA26: =Y26*Z26 -> 0
T27: =IFERROR(VLOOKUP(S27,'(cata_mp)'!C42:I16445,2,FALSE)," ") | U27: - | V27: =IFERROR(INDEX(opción_descripción,MATCH(' (Explo_MP)'!$U27,opción,0))," ") -> Sin Opc. | W27: =IFERROR(VLOOKUP(S27,'(cata_mp)'!C45:I16448,5,FALSE)," ") | X27: {=IFERROR(INDEX('(cata_mp)'!H44:H16447,MATCH(' (Explo_MP)'!S27&' (Explo_MP)'!U27,'(cata_mp)'!C44:C16447&'(cata_mp)'!E44:E16447,0)), " ")} | Y27: {=IFERROR(INDEX('(cata_mp)'!I:I,MATCH(' (Explo_MP)'!S27&' (Explo_MP)'!U27,'(cata_mp)'!C:C&'(cata_mp)'!E:E,0)),"$ 0")} -> $ 0 | AA27: =Y27*Z27 -> 0
Y28: =P19 -> id_02 | Z28: =P19&" costo_total:" -> id_02 costo_total: | AA28: =+SUM(AA22:AA27) -> 0
P32: ='REG-DCC-IDP-031 (T_d_C) '!D24 -> id_03
R33: familia_de_operación | S33: articulo | T33: descripción | U33: opción | V33: opción_descripción | W33: unidad | X33: fecha_última_compra | Y33: costo_última_compra | Z33: consumo_unitaruio | AA33: costo_unitario
T34: ='REG-DCC-IDP-031 (T_d_C) '!E24 -> 0
T35: =IFERROR(VLOOKUP(S35,'(cata_mp)'!C47:I16450,2,FALSE)," ") | U35: - | V35: =IFERROR(INDEX(opción_descripción,MATCH(' (Explo_MP)'!$U35,opción,0))," ") -> Sin Opc. | W35: =IFERROR(VLOOKUP(S35,'(cata_mp)'!C49:I16452,5,FALSE)," ") | X35: {=IFERROR(INDEX('(cata_mp)'!H48:H16451,MATCH(' (Explo_MP)'!S35&' (Explo_MP)'!U35,'(cata_mp)'!C48:C16451&'(cata_mp)'!E48:E16451,0)), " ")} | Y35: {=IFERROR(INDEX('(cata_mp)'!I:I,MATCH(' (Explo_MP)'!S35&' (Explo_MP)'!U35,'(cata_mp)'!C:C&'(cata_mp)'!E:E,0)),"$ 0")} -> $ 0 | AA35: =Y35*Z35 -> 0
T36: =IFERROR(VLOOKUP(S36,'(cata_mp)'!C48:I16451,2,FALSE)," ") | U36: - | V36: =IFERROR(INDEX(opción_descripción,MATCH(' (Explo_MP)'!$U36,opción,0))," ") -> Sin Opc. | W36: =IFERROR(VLOOKUP(S36,'(cata_mp)'!C50:I16453,5,FALSE)," ") | X36: {=IFERROR(INDEX('(cata_mp)'!H49:H16452,MATCH(' (Explo_MP)'!S36&' (Explo_MP)'!U36,'(cata_mp)'!C49:C16452&'(cata_mp)'!E49:E16452,0)), " ")} | Y36: {=IFERROR(INDEX('(cata_mp)'!I:I,MATCH(' (Explo_MP)'!S36&' (Explo_MP)'!U36,'(cata_mp)'!C:C&'(cata_mp)'!E:E,0)),"$ 0")} -> $ 0 | AA36: =Y36*Z36 -> 0
T37: =IFERROR(VLOOKUP(S37,'(cata_mp)'!C49:I16452,2,FALSE)," ") | U37: - | V37: =IFERROR(INDEX(opción_descripción,MATCH(' (Explo_MP)'!$U37,opción,0))," ") -> Sin Opc. | W37: =IFERROR(VLOOKUP(S37,'(cata_mp)'!C51:I16454,5,FALSE)," ") | X37: {=IFERROR(INDEX('(cata_mp)'!H50:H16453,MATCH(' (Explo_MP)'!S37&' (Explo_MP)'!U37,'(cata_mp)'!C50:C16453&'(cata_mp)'!E50:E16453,0)), " ")} | Y37: {=IFERROR(INDEX('(cata_mp)'!I:I,MATCH(' (Explo_MP)'!S37&' (Explo_MP)'!U37,'(cata_mp)'!C:C&'(cata_mp)'!E:E,0)),"$ 0")} -> $ 0 | AA37: =Y37*Z37 -> 0
T38: =IFERROR(VLOOKUP(S38,'(cata_mp)'!C50:I16453,2,FALSE)," ") | U38: - | V38: =IFERROR(INDEX(opción_descripción,MATCH(' (Explo_MP)'!$U38,opción,0))," ") -> Sin Opc. | W38: =IFERROR(VLOOKUP(S38,'(cata_mp)'!C52:I16455,5,FALSE)," ") | X38: {=IFERROR(INDEX('(cata_mp)'!H51:H16454,MATCH(' (Explo_MP)'!S38&' (Explo_MP)'!U38,'(cata_mp)'!C51:C16454&'(cata_mp)'!E51:E16454,0)), " ")} | Y38: {=IFERROR(INDEX('(cata_mp)'!I:I,MATCH(' (Explo_MP)'!S38&' (Explo_MP)'!U38,'(cata_mp)'!C:C&'(cata_mp)'!E:E,0)),"$ 0")} -> $ 0 | AA38: =Y38*Z38 -> 0
T39: =IFERROR(VLOOKUP(S39,'(cata_mp)'!C51:I16454,2,FALSE)," ") | U39: - | V39: =IFERROR(INDEX(opción_descripción,MATCH(' (Explo_MP)'!$U39,opción,0))," ") -> Sin Opc. | W39: =IFERROR(VLOOKUP(S39,'(cata_mp)'!C53:I16456,5,FALSE)," ") | X39: {=IFERROR(INDEX('(cata_mp)'!H52:H16455,MATCH(' (Explo_MP)'!S39&' (Explo_MP)'!U39,'(cata_mp)'!C52:C16455&'(cata_mp)'!E52:E16455,0)), " ")} | Y39: {=IFERROR(INDEX('(cata_mp)'!I:I,MATCH(' (Explo_MP)'!S39&' (Explo_MP)'!U39,'(cata_mp)'!C:C&'(cata_mp)'!E:E,0)),"$ 0")} -> $ 0 | AA39: =Y39*Z39 -> 0
Y40: =P32 -> id_03 | Z40: =P32&" costo_total:" -> id_03 costo_total: | AA40: =+SUM(AA35:AA39) -> 0
P44: ='REG-DCC-IDP-031 (T_d_C) '!D25 -> id_04
R45: familia_de_operación | S45: articulo | T45: descripción | U45: opción | V45: opción_descripción | W45: unidad | X45: fecha_última_compra | Y45: costo_última_compra | Z45: consumo_unitaruio | AA45: costo_unitario
T46: ='REG-DCC-IDP-031 (T_d_C) '!E25 -> 0
T47: =IFERROR(VLOOKUP(S47,'(cata_mp)'!C66:I16469,2,FALSE)," ") | U47: - | V47: =IFERROR(INDEX(opción_descripción,MATCH(' (Explo_MP)'!$U47,opción,0))," ") -> Sin Opc. | W47: =IFERROR(VLOOKUP(S47,'(cata_mp)'!C68:I16471,5,FALSE)," ") | X47: {=IFERROR(INDEX('(cata_mp)'!H67:H16470,MATCH(' (Explo_MP)'!S47&' (Explo_MP)'!U47,'(cata_mp)'!C67:C16470&'(cata_mp)'!E67:E16470,0)), " ")} | Y47: {=IFERROR(INDEX('(cata_mp)'!I:I,MATCH(' (Explo_MP)'!S47&' (Explo_MP)'!U47,'(cata_mp)'!C:C&'(cata_mp)'!E:E,0)),"$ 0")} -> $ 0 | AA47: =Y47*Z47 -> 0
T48: =IFERROR(VLOOKUP(S48,'(cata_mp)'!C67:I16470,2,FALSE)," ") | U48: - | V48: =IFERROR(INDEX(opción_descripción,MATCH(' (Explo_MP)'!$U48,opción,0))," ") -> Sin Opc. | W48: =IFERROR(VLOOKUP(S48,'(cata_mp)'!C69:I16472,5,FALSE)," ") | X48: {=IFERROR(INDEX('(cata_mp)'!H68:H16471,MATCH(' (Explo_MP)'!S48&' (Explo_MP)'!U48,'(cata_mp)'!C68:C16471&'(cata_mp)'!E68:E16471,0)), " ")} | Y48: {=IFERROR(INDEX('(cata_mp)'!I:I,MATCH(' (Explo_MP)'!S48&' (Explo_MP)'!U48,'(cata_mp)'!C:C&'(cata_mp)'!E:E,0)),"$ 0")} -> $ 0 | AA48: =Y48*Z48 -> 0
T49: =IFERROR(VLOOKUP(S49,'(cata_mp)'!C68:I16471,2,FALSE)," ") | U49: - | V49: =IFERROR(INDEX(opción_descripción,MATCH(' (Explo_MP)'!$U49,opción,0))," ") -> Sin Opc. | W49: =IFERROR(VLOOKUP(S49,'(cata_mp)'!C70:I16473,5,FALSE)," ") | X49: {=IFERROR(INDEX('(cata_mp)'!H69:H16472,MATCH(' (Explo_MP)'!S49&' (Explo_MP)'!U49,'(cata_mp)'!C69:C16472&'(cata_mp)'!E69:E16472,0)), " ")} | Y49: {=IFERROR(INDEX('(cata_mp)'!I:I,MATCH(' (Explo_MP)'!S49&' (Explo_MP)'!U49,'(cata_mp)'!C:C&'(cata_mp)'!E:E,0)),"$ 0")} -> $ 0 | AA49: =Y49*Z49 -> 0
T50: =IFERROR(VLOOKUP(S50,'(cata_mp)'!C69:I16472,2,FALSE)," ") | U50: - | V50: =IFERROR(INDEX(opción_descripción,MATCH(' (Explo_MP)'!$U50,opción,0))," ") -> Sin Opc. | W50: =IFERROR(VLOOKUP(S50,'(cata_mp)'!C71:I16474,5,FALSE)," ") | X50: {=IFERROR(INDEX('(cata_mp)'!H70:H16473,MATCH(' (Explo_MP)'!S50&' (Explo_MP)'!U50,'(cata_mp)'!C70:C16473&'(cata_mp)'!E70:E16473,0)), " ")} | Y50: {=IFERROR(INDEX('(cata_mp)'!I:I,MATCH(' (Explo_MP)'!S50&' (Explo_MP)'!U50,'(cata_mp)'!C:C&'(cata_mp)'!E:E,0)),"$ 0")} -> $ 0 | AA50: =Y50*Z50 -> 0
T51: =IFERROR(VLOOKUP(S51,'(cata_mp)'!C70:I16473,2,FALSE)," ") | U51: - | V51: =IFERROR(INDEX(opción_descripción,MATCH(' (Explo_MP)'!$U51,opción,0))," ") -> Sin Opc. | W51: =IFERROR(VLOOKUP(S51,'(cata_mp)'!C72:I16475,5,FALSE)," ") | X51: {=IFERROR(INDEX('(cata_mp)'!H71:H16474,MATCH(' (Explo_MP)'!S51&' (Explo_MP)'!U51,'(cata_mp)'!C71:C16474&'(cata_mp)'!E71:E16474,0)), " ")} | Y51: {=IFERROR(INDEX('(cata_mp)'!I:I,MATCH(' (Explo_MP)'!S51&' (Explo_MP)'!U51,'(cata_mp)'!C:C&'(cata_mp)'!E:E,0)),"$ 0")} -> $ 0 | AA51: =Y51*Z51 -> 0
...

Sheet (cata_mp)
C2: Consulta MP, MD y MI última Compra_20260410
C3: articulo | D3: descripción | E3: opción | F3: opción_descripción | G3: unidad | H3: fecha_última_compra | I3: costo_última_compra | J3: largo | K3: ancho | L3: desarrollo | M3: clave_comercial
C4: MVLPTA270000F0 | D4: (SCREW CAPS FOR VITRINE) TAPA AUTO ADHERIBLE PARA RETOCAR COLOR BLANCO ABSOLUTO 4159 MASISA (PLANILLA) - "TADB4159" | E4: - | F4: Sin Opc. | G4: pieza | H4: 43424 | I4: 9 | L4: 0 | M4: TADB4159
C5: MLEAAR03000000 | D5: 1:20 R/C VW BEETLE 4718487746361 27026 - "27026" | E5: - | F5: Sin Opc. | G5: pieza | H5: 43829 | I5: 119.73 | L5: 0 | M5: 27026
C6: MLEAAR17000000 | D6: 1:24 LAMBORGHINIHURACAN PERFORMANTE VERSION 4718487746699 27059 - "27059" | E6: - | F6: Sin Opc. | G6: pieza | H6: 43829 | I6: 119.97 | L6: 0 | M6: 27059
C7: MLEAAR16000000 | D7: 1:24 LAMBORGHINILP770-4 CENTENNIAL EDITION 4718487746354 27058 - "27058" | E7: - | F7: Sin Opc. | G7: pieza | H7: 43829 | I7: 121.66 | L7: 0 | M7: 27058
C8: MLEAAR15000000 | D8: 1:24 R/C AUDI R8 4718487746347 27057 - "27057" | E8: - | F8: Sin Opc. | G8: pieza | H8: 43829 | I8: 117.56 | L8: 0 | M8: 27057
C9: MLEAAR10000000 | D9: 1:24 R/C BENTLY GT SUPERSPORT 4718487746439 27040 - "27040" | E9: - | F9: Sin Opc. | G9: pieza | H9: 43829 | I9: 117.56 | L9: 0 | M9: 27040
C10: MLEAAR07000000 | D10: 1:24 R/C BENZ SLS 4718487746408 27046 - "27046" | E10: - | F10: Sin Opc. | G10: pieza | H10: 43829 | I10: 117.56 | L10: 0 | M10: 27046
C11: MLEAAR12000000 | D11: 1:24 R/C FORD MUSTANG GT500 4718487746453 27050 - "27050" | E11: - | F11: Sin Opc. | G11: pieza | H11: 43829 | I11: 117.56 | L11: 0 | M11: 27050
C12: MLEAAR08000000 | D12: 1:24 R/C HUMMER H2 4718487746415 27020 - "27020" | E12: - | F12: Sin Opc. | G12: pieza | H12: 43829 | I12: 133.22 | L12: 0 | M12: 27020
C13: MLEAAR18000000 | D13: 1:24 R/C LAMBORGHINI LP670 4718487745104 - "" | E13: - | F13: Sin Opc. | G13: pieza | L13: 0 | M13: 27018
C14: MLEAAR04000000 | D14: 1:24 R/C LAMBORGHINI LP670 4718487746378 27018 - "27018" | E14: - | F14: Sin Opc. | G14: pieza | H14: 43829 | I14: 117.56 | L14: 0 | M14: 27018
C15: MLEAAR06000000 | D15: 1:24 R/C LAMBORGHINI LP700 4718487746392 27021 - "27021 4" | E15: - | F15: Sin Opc. | G15: pieza | H15: 43829 | I15: 117.56 | L15: 0 | M15: 27021 4
C16: MLEAAR05000000 | D16: 1:24 R/C LAMBORGHINI REVENTON 4718487746385 27024 - "27024" | E16: - | F16: Sin Opc. | G16: pieza | H16: 43829 | I16: 117.56 | L16: 0 | M16: 27024
C17: MLEAAR11000000 | D17: 1:24 R/C LAMBORGHINI VENENO 4718487746446 27043 - "27043" | E17: - | F17: Sin Opc. | G17: pieza | H17: 43829 | I17: 117.56 | L17: 0 | M17: 27043
C18: MLEAAR14000000 | D18: 1:24 R/C MASERATI SUV 4718487746330 27056 - "27056" | E18: - | F18: Sin Opc. | G18: pieza | H18: 43829 | I18: 119.73 | L18: 0 | M18: 27026
C19: MLEAAR09000000 | D19: 1:24 R/C MERCEDES BENZ G55 4718487746422 27029 - "27029" | E19: - | F19: Sin Opc. | G19: pieza | H19: 43829 | I19: 119.73 | L19: 0 | M19: 27029
C20: MLEAAR13000000 | D20: 1:24 R/C PAGANI HUAYRA 4718487746323 27042 - "27042" | E20: - | F20: Sin Opc. | G20: pieza | H20: 43829 | I20: 117.56 | L20: 0 | M20: 27042
C21: MLEECA00840000 | D21: 12" PASS THRU BE05926-BK-12 - "BE05926BK12" | E21: - | F21: Sin Opc. | G21: pieza | L21: 0 | M21: BE05926BK12
C22: MDMECA00030000 | D22: 15A RECEPTACLE, C HEIGHT,C1 ,COLOR -- BE52426-3-C-1-C | E22: - | F22: Sin Opc. | G22: pieza | H22: 45881 | I22: 90.73 | L22: 0 | M22: BE52426-3-C-1-C
C23: MDMPLO02020102 | D23: 2 PIEZAS LOGOTIPO LETRA "V" EN CORTE LASER DE 232 X 147 mm ESPESOR 3 mm EN ACRILICO ROJO, SEGUN PLANO, 8 PIEZAS RECTANGULARES DE 510 X 36 mm ESPESOR 3 mm EN ACRILICO ROJO y 2 KIT DE ILUMINACION PARA PEDESTAL VONHAUCKE -- COMEVH132-LOG | E23: - | F23: Sin Opc. | G23: pieza | H23: 45961 | I23: 6632 | L23: 0 | M23: BESMSTRT22EMWHU172LR
C24: MVLECA270000D7 | D24: 2 PUERTOS ELECTRICOS, 1 PUERTO VACIO Y UN USB DE CARGA DOBLE ESTRUCTURA MET. MONTAJE ALTURA DE LA SUPERF. DE TRABAJO, ACCESO A TODOS LOS PUERTOS 72" PULGADAS DE CABLE C/CLAVIJA DE 3 POLOS, SE COLOCA LATERAL, CON KIT DE ADAPTADORES-"BESMSTRT22EMWHU172LR" | E24: - | F24: Sin Opc. | G24: pieza | H24: 43650 | I24: 844.2 | L24: 0 | M24: G10044215
C25: MVLXET000000C1 | D25: 24" (620 mm) GLASS SHELF WITH EDGE STRIP AND LED STRIP (COMPLETE ITEM) 3000 KELVIN "100-442.15" - "G10044215" | E25: - | F25: Sin Opc. | G25: pieza | H25: 43706 | I25: 5217.37 | L25: 0
C26: MVLEEM08000000 | D26: 24" (620MM) GLASS SHELF WITH EDGE STRIP AND LED STRIP (COMPLETE ITEM) 3000 KELVIN "100-442.15" - "" | E26: - | F26: Sin Opc. | G26: pieza | H26: 43277 | I26: 272.06 | L26: 0
C27: MVLEEM03000000 | D27: 24V DISTRIBUTOR, 8-WAY WITH SWITCH INPUT 1640 mm (2x16W) WHITE (13899519) | E27: - | F27: Sin Opc. | G27: pieza | H27: 43642 | I27: 702.91 | L27: 0 | M27: PECANTV32ING
C28: MVLPPC015015E8 | D28: 25 METERS OF WALNUT EDGE BANDING -- "PECANTV32ING" | E28: - | F28: Sin Opc. | G28: m | L28: 0 | M28: DISCSOFT
C29: MVLADC07000000 | D29: 3M HOOKIT SOFT INTERFACE PAD CLAVE : 5777, DE 6" Ø - "DISCSOFT" | E29: - | F29: Sin Opc. | G29: pieza | H29: 43578 | I29: 181.03 | L29: 0 | M29: BE52463-3-42
C30: MDMECA00050000 | D30: 42" F/F PASS THRU -- BE52463-3-42 | E30: - | F30: Sin Opc. | G30: pieza | H30: 45867 | I30: 346.07 | L30: 0 | M30: BE52468-3-42
C31: MDMECA00040000 | D31: 42" F/F/M 3-WAY PASS THRU -- BE52468-3-42 | E31: - | F31: Sin Opc. | G31: pieza | H31: 45867 | I31: 370.39 | L31: 0 | M31: BE52463-3-48
C32: MDMECA00090000 | D32: 48" F/F PASS THRU -- BE52463-3-48 | E32: - | F32: Sin Opc. | G32: pieza | L32: 0 | M32: BE52463-3-54
C33: MDMECA00080000 | D33: 54" F/F PASS THRU -- BE52463-3-54 | E33: - | F33: Sin Opc. | G33: pieza | H33: 45867 | I33: 398.05 | L33: 0 | M33: BE52468-3-54
C34: MDMECA00070000 | D34: 54" F/F/M 3-WAY PASS THRU -- BE52468-3-54 | E34: - | F34: Sin Opc. | G34: pieza | H34: 45881 | I34: 388.81 | L34: 0 | M34: CP-JLR-004
C35: MVLEKE0000D500 | D35: 6 mm GLASS SHELF WITH LED/ALU PROFILE ON FRONT - CP-JLR-004 | E35: - | F35: Sin Opc. | G35: pieza | L35: 0
C36: MVLAKA00190000 | D36: 6mm ACM ILLUMINATED SHELF PR-EH-503 CUBIC - | E36: - | F36: Sin Opc. | G36: pieza | H36: 43342 | I36: 1842.5 | L36: 0 | M36: BE5325121STST15A72
C37: MLEECA00880000 | D37: 72" POWER INFEED CORD BE53251-2-1-ST-ST15A-72 - "BE5325121STST15A72" | E37: - | F37: Sin Opc. | G37: pieza | H37: 45195 | I37: 617.52 | L37: 0 | M37: BE0711672
C38: MLEECA00820000 | D38: 72" SMART INFEED BE07116-72 - "BE0711672" | E38: - | F38: Sin Opc. | G38: pieza | L38: 0 | M38: BE53251-3-1-ST-ST15A
C39: MDMECA00010000 | D39: 72" STRAIGHT CORDED POWER ENTRY, 15AMP, CIRCUIT 1 -- BE53251-3-1-ST-ST15A-72 | E39: - | F39: Sin Opc. | G39: pieza | H39: 45881 | I39: 662.75 | L39: 0
C40: MVLEEM04000000 | D40: 75 W LED CONVERTER WITH US PLUG "138-978.19" - "" | E40: - | F40: Sin Opc. | G40: pieza | H40: 43642 | I40: 2886.74 | L40: 0 | M40: ADVACEEM
C41: MLEXSA12S900G5 | D41: A EN CAJA MODELO ADVACE RESPALDO Y ASIENTO TAPIZADO EN MESH NEGRO, CON BASE DE TRINEO CROMADA, BRAZOS ES UNA SOLA PIEZA - "ADVACEEM" | E41: - | F41: Sin Opc. | G41: pieza | H41: 44215 | I41: 4319 | L41: 0 | M41: 70300701
...

Sheet  (cuanti_mp)
C1: desarrollo y cantidad de pieza a calcular | J1: material | L1: especificación técnica de materia prima seleccionada | P1: consumos por piezas | S1: consumo total | W1: calculadora de aprovechamiento por tablero
C2: parte | D2: n° partes | E2: pieza | F2: n° piezas | G2: largo | H2: ancho | J2: articulo | K2: opción | L2: descripción | M2: u.m. | N2: largo | O2: ancho | P2: consumo de tablero | Q2: consumo de polvo | S2: articulo | T2: descripción | U2: consumo | W2: 3' x 8' | X2: cant. max | Y2: 3' x 10' | Z2: cant. max | AA2: 4' x 8' | AB2: cant. max | AC2: 4' x 10' | AD2: cant. max
A3: 1 | C3: loker | D3: 1 | E3: loker | F3: 23 | G3: 0.1 | H3: 1.22 | J3: MVLSLA05260502 | L3: =IFERROR(VLOOKUP(J3,articulo:clave_comercial,2,0)," ") -> LAMINA NEGRA HOJA 3 X 10 CALIBRE 20 ACERO 1008 - LN20310 | M3: =UPPER(IFERROR(VLOOKUP(J3,articulo:clave_comercial,5,0)," ")) -> HOJA | N3: =IFERROR(IF(VLOOKUP(J3,articulo:clave_comercial,8,0)=0," ",VLOOKUP(J3,articulo:clave_comercial,8,0))," ") | O3: =IFERROR(IF(VLOOKUP(J3,articulo:clave_comercial,9,0)=0," ",VLOOKUP(J3,articulo:clave_comercial,9,0))," ") | P3: =IFERROR(IF(M3="HOJA",(D3*F3)/MAX(ROUNDDOWN((N3/G3),0)*ROUNDDOWN((O3/H3),0),ROUNDDOWN((N3/H3),0)*ROUNDDOWN((O3/G3),0)),IF(M3="HOJA ",(D3*F3)/MAX(ROUNDDOWN((N3/G3),0)*ROUNDDOWN((O3/H3),0),ROUNDDOWN((N3/H3),0)*ROUNDDOWN((O3/G3),0)),IF(M3="M",G3,IF(AND(M3="PIEZA",G3<>0),(D3*F3)/ROUNDDOWN((N3/G3),0),IF(M3="PIEZA",(D3*F3),IF(M3="CAJA",(D3*F3),IF(M3="DM2",(D3*F3),IF(M3="FT",(D3*F3),IF(M3="JGO",(D3*F3),IF(M3="KG",(D3*F3),IF(M3="LB",(D3*F3),IF(M3="LT",(D3*F3),IF(M3="M2",(D3*F3),IF(M3="M3",(D3*F3),IF(M3="ROLLO",(D3*F3),IF(M3="SQYDS",(D3*F3),IF(M3="UD./SERV.",(D3*F3),IF(M3="YD",(D3*F3)," ")))))))))))))))))),"") | Q3: =IFERROR(IF(M3="HOJA",D3*F3*G3*H3*2*0.125,IF(AND(M3="PIEZA",H3=0),D3*F3*G3*VLOOKUP(J3,articulo:clave_comercial,10,0)*0.125,0))," ") -> 0.702 | S3: {=IFERROR(INDEX($J$3:$J$52,MATCH(0,INDEX(COUNTIF(S2:$S$2,$J$3:$J$52),0,0),0))," ")} -> MVLSLA05260502 | T3: {=IFERROR(INDEX($L$3:$L$52,MATCH(0,INDEX(COUNTIF($T2:T$2,$L$3:$L$52),0,0),0))," ")} -> LAMINA NEGRA HOJA 3 X 10 CALIBRE 20 ACERO 1008 - LN20310 | U3: =IFERROR(IF(AND(VLOOKUP(S3,$J$3:$Q$218,4,0)="KG",VLOOKUP(S3,$J$3:$Q$218,7,0)=0,VLOOKUP(S3,$J$3:$Q$218,8,0)=0),SUM($Q$3:$Q$218),SUMIF($J$3:$J$218,S3,$P$3:$P$218)),"") -> 0 | W3: =IFERROR(IF(OR(M3="HOJA",M3="HOJA "),((MAX(ROUNDDOWN((0.915/G3),0)*ROUNDDOWN((2.44/H3),0),ROUNDDOWN((0.915/H3),0)*ROUNDDOWN((2.44/G3),0)))*G3*H3)/(0.915*2.44),""),"") -> 0.98 | X3: =IFERROR(MAX(ROUNDDOWN((0.915/G3),0)*ROUNDDOWN((2.44/H3),0),ROUNDDOWN((0.915/H3),0)*ROUNDDOWN((2.44/G3),0)),"") -> 18 | Y3: =IFERROR(IF(OR(M3="HOJA",M3="HOJA "),((MAX(ROUNDDOWN((0.915/G3),0)*ROUNDDOWN((3.05/H3),0),ROUNDDOWN((0.915/H3),0)*ROUNDDOWN((3.05/G3),0)))*G3*H3)/(0.915*3.05),""),"") -> 0.79 | Z3: =IFERROR(MAX(ROUNDDOWN((0.915/G3),0)*ROUNDDOWN((3.05/H3),0),ROUNDDOWN((0.915/H3),0)*ROUNDDOWN((3.05/G3),0)),"") -> 18 | AA3: =IFERROR(IF(OR(M3="HOJA",M3="HOJA "),((MAX(ROUNDDOWN((1.22/G3),0)*ROUNDDOWN((2.44/H3),0),ROUNDDOWN((1.22/H3),0)*ROUNDDOWN((2.44/G3),0)))*G3*H3)/(1.22*2.44),""),"") -> 0.98 | AB3: =IFERROR(MAX(ROUNDDOWN((1.22/G3),0)*ROUNDDOWN((2.44/H3),0),ROUNDDOWN((1.22/H3),0)*ROUNDDOWN((2.44/G3),0)),"") -> 24 | AC3: =IFERROR(IF(OR(M3="HOJA",M3="HOJA "),((MAX(ROUNDDOWN((1.22/G3),0)*ROUNDDOWN((3.05/H3),0),ROUNDDOWN((1.22/H3),0)*ROUNDDOWN((3.05/G3),0)))*G3*H3)/(1.22*3.05),""),"") -> 0.98 | AD3: =IFERROR(MAX(ROUNDDOWN((1.22/G3),0)*ROUNDDOWN((3.05/H3),0),ROUNDDOWN((1.22/H3),0)*ROUNDDOWN((3.05/G3),0)),"") -> 30
L4: =IFERROR(VLOOKUP(J4,articulo:clave_comercial,2,0)," ") | M4: =UPPER(IFERROR(VLOOKUP(J4,articulo:clave_comercial,5,0)," ")) | N4: =IFERROR(IF(VLOOKUP(J4,articulo:clave_comercial,8,0)=0," ",VLOOKUP(J4,articulo:clave_comercial,8,0))," ") | O4: =IFERROR(IF(VLOOKUP(J4,articulo:clave_comercial,9,0)=0," ",VLOOKUP(J4,articulo:clave_comercial,9,0))," ") | P4: =IFERROR(IF(M4="HOJA",(D4*F4)/MAX(ROUNDDOWN((N4/G4),0)*ROUNDDOWN((O4/H4),0),ROUNDDOWN((N4/H4),0)*ROUNDDOWN((O4/G4),0)),IF(M4="HOJA ",(D4*F4)/MAX(ROUNDDOWN((N4/G4),0)*ROUNDDOWN((O4/H4),0),ROUNDDOWN((N4/H4),0)*ROUNDDOWN((O4/G4),0)),IF(M4="M",G4,IF(AND(M4="PIEZA",G4<>0),(D4*F4)/ROUNDDOWN((N4/G4),0),IF(M4="PIEZA",(D4*F4),IF(M4="CAJA",(D4*F4),IF(M4="DM2",(D4*F4),IF(M4="FT",(D4*F4),IF(M4="JGO",(D4*F4),IF(M4="KG",(D4*F4),IF(M4="LB",(D4*F4),IF(M4="LT",(D4*F4),IF(M4="M2",(D4*F4),IF(M4="M3",(D4*F4),IF(M4="ROLLO",(D4*F4),IF(M4="SQYDS",(D4*F4),IF(M4="UD./SERV.",(D4*F4),IF(M4="YD",(D4*F4)," ")))))))))))))))))),"") | Q4: =IFERROR(IF(M4="HOJA",D4*F4*G4*H4*2*0.125,IF(AND(M4="PIEZA",H4=0),D4*F4*G4*VLOOKUP(J4,articulo:clave_comercial,10,0)*0.125,0))," ") -> 0 | S4: {=IFERROR(INDEX($J$3:$J$52,MATCH(0,INDEX(COUNTIF(S$2:$S3,$J$3:$J$52),0,0),0))," ")} -> 0 | T4: {=IFERROR(INDEX($L$3:$L$52,MATCH(0,INDEX(COUNTIF($T$2:T3,$L$3:$L$52),0,0),0))," ")} | U4: =IFERROR(IF(AND(VLOOKUP(S4,$J$3:$Q$218,4,0)="KG",VLOOKUP(S4,$J$3:$Q$218,7,0)=0,VLOOKUP(S4,$J$3:$Q$218,8,0)=0),SUM($Q$3:$Q$218),SUMIF($J$3:$J$218,S4,$P$3:$P$218)),"") | W4: =IFERROR(IF(OR(M4="HOJA",M4="HOJA "),((MAX(ROUNDDOWN((0.915/G4),0)*ROUNDDOWN((2.44/H4),0),ROUNDDOWN((0.915/H4),0)*ROUNDDOWN((2.44/G4),0)))*G4*H4)/(0.915*2.44),""),"") | X4: =IFERROR(MAX(ROUNDDOWN((0.915/G4),0)*ROUNDDOWN((2.44/H4),0),ROUNDDOWN((0.915/H4),0)*ROUNDDOWN((2.44/G4),0)),"") | Y4: =IFERROR(IF(OR(M4="HOJA",M4="HOJA "),((MAX(ROUNDDOWN((0.915/G4),0)*ROUNDDOWN((3.05/H4),0),ROUNDDOWN((0.915/H4),0)*ROUNDDOWN((3.05/G4),0)))*G4*H4)/(0.915*3.05),""),"") | Z4: =IFERROR(MAX(ROUNDDOWN((0.915/G4),0)*ROUNDDOWN((3.05/H4),0),ROUNDDOWN((0.915/H4),0)*ROUNDDOWN((3.05/G4),0)),"") | AA4: =IFERROR(IF(OR(M4="HOJA",M4="HOJA "),((MAX(ROUNDDOWN((1.22/G4),0)*ROUNDDOWN((2.44/H4),0),ROUNDDOWN((1.22/H4),0)*ROUNDDOWN((2.44/G4),0)))*G4*H4)/(1.22*2.44),""),"") | AB4: =IFERROR(MAX(ROUNDDOWN((1.22/G4),0)*ROUNDDOWN((2.44/H4),0),ROUNDDOWN((1.22/H4),0)*ROUNDDOWN((2.44/G4),0)),"") | AC4: =IFERROR(IF(OR(M4="HOJA",M4="HOJA "),((MAX(ROUNDDOWN((1.22/G4),0)*ROUNDDOWN((3.05/H4),0),ROUNDDOWN((1.22/H4),0)*ROUNDDOWN((3.05/G4),0)))*G4*H4)/(1.22*3.05),""),"") | AD4: =IFERROR(MAX(ROUNDDOWN((1.22/G4),0)*ROUNDDOWN((3.05/H4),0),ROUNDDOWN((1.22/H4),0)*ROUNDDOWN((3.05/G4),0)),"")
L5: =IFERROR(VLOOKUP(J5,articulo:clave_comercial,2,0)," ") | M5: =UPPER(IFERROR(VLOOKUP(J5,articulo:clave_comercial,5,0)," ")) | N5: =IFERROR(IF(VLOOKUP(J5,articulo:clave_comercial,8,0)=0," ",VLOOKUP(J5,articulo:clave_comercial,8,0))," ") | O5: =IFERROR(IF(VLOOKUP(J5,articulo:clave_comercial,9,0)=0," ",VLOOKUP(J5,articulo:clave_comercial,9,0))," ") | P5: =IFERROR(IF(M5="HOJA",(D5*F5)/MAX(ROUNDDOWN((N5/G5),0)*ROUNDDOWN((O5/H5),0),ROUNDDOWN((N5/H5),0)*ROUNDDOWN((O5/G5),0)),IF(M5="HOJA ",(D5*F5)/MAX(ROUNDDOWN((N5/G5),0)*ROUNDDOWN((O5/H5),0),ROUNDDOWN((N5/H5),0)*ROUNDDOWN((O5/G5),0)),IF(M5="M",G5,IF(AND(M5="PIEZA",G5<>0),(D5*F5)/ROUNDDOWN((N5/G5),0),IF(M5="PIEZA",(D5*F5),IF(M5="CAJA",(D5*F5),IF(M5="DM2",(D5*F5),IF(M5="FT",(D5*F5),IF(M5="JGO",(D5*F5),IF(M5="KG",(D5*F5),IF(M5="LB",(D5*F5),IF(M5="LT",(D5*F5),IF(M5="M2",(D5*F5),IF(M5="M3",(D5*F5),IF(M5="ROLLO",(D5*F5),IF(M5="SQYDS",(D5*F5),IF(M5="UD./SERV.",(D5*F5),IF(M5="YD",(D5*F5)," ")))))))))))))))))),"") | Q5: =IFERROR(IF(M5="HOJA",D5*F5*G5*H5*2*0.125,IF(AND(M5="PIEZA",H5=0),D5*F5*G5*VLOOKUP(J5,articulo:clave_comercial,10,0)*0.125,0))," ") -> 0 | S5: {=IFERROR(INDEX($J$3:$J$52,MATCH(0,INDEX(COUNTIF(S$2:$S4,$J$3:$J$52),0,0),0))," ")} | T5: {=IFERROR(INDEX($L$3:$L$52,MATCH(0,INDEX(COUNTIF($T$2:T4,$L$3:$L$52),0,0),0))," ")} | U5: =IFERROR(IF(AND(VLOOKUP(S5,$J$3:$Q$218,4,0)="KG",VLOOKUP(S5,$J$3:$Q$218,7,0)=0,VLOOKUP(S5,$J$3:$Q$218,8,0)=0),SUM($Q$3:$Q$218),SUMIF($J$3:$J$218,S5,$P$3:$P$218)),"") | W5: =IFERROR(IF(OR(M5="HOJA",M5="HOJA "),((MAX(ROUNDDOWN((0.915/G5),0)*ROUNDDOWN((2.44/H5),0),ROUNDDOWN((0.915/H5),0)*ROUNDDOWN((2.44/G5),0)))*G5*H5)/(0.915*2.44),""),"") | X5: =IFERROR(MAX(ROUNDDOWN((0.915/G5),0)*ROUNDDOWN((2.44/H5),0),ROUNDDOWN((0.915/H5),0)*ROUNDDOWN((2.44/G5),0)),"") | Y5: =IFERROR(IF(OR(M5="HOJA",M5="HOJA "),((MAX(ROUNDDOWN((0.915/G5),0)*ROUNDDOWN((3.05/H5),0),ROUNDDOWN((0.915/H5),0)*ROUNDDOWN((3.05/G5),0)))*G5*H5)/(0.915*3.05),""),"") | Z5: =IFERROR(MAX(ROUNDDOWN((0.915/G5),0)*ROUNDDOWN((3.05/H5),0),ROUNDDOWN((0.915/H5),0)*ROUNDDOWN((3.05/G5),0)),"") | AA5: =IFERROR(IF(OR(M5="HOJA",M5="HOJA "),((MAX(ROUNDDOWN((1.22/G5),0)*ROUNDDOWN((2.44/H5),0),ROUNDDOWN((1.22/H5),0)*ROUNDDOWN((2.44/G5),0)))*G5*H5)/(1.22*2.44),""),"") | AB5: =IFERROR(MAX(ROUNDDOWN((1.22/G5),0)*ROUNDDOWN((2.44/H5),0),ROUNDDOWN((1.22/H5),0)*ROUNDDOWN((2.44/G5),0)),"") | AC5: =IFERROR(IF(OR(M5="HOJA",M5="HOJA "),((MAX(ROUNDDOWN((1.22/G5),0)*ROUNDDOWN((3.05/H5),0),ROUNDDOWN((1.22/H5),0)*ROUNDDOWN((3.05/G5),0)))*G5*H5)/(1.22*3.05),""),"") | AD5: =IFERROR(MAX(ROUNDDOWN((1.22/G5),0)*ROUNDDOWN((3.05/H5),0),ROUNDDOWN((1.22/H5),0)*ROUNDDOWN((3.05/G5),0)),"")
L6: =IFERROR(VLOOKUP(J6,articulo:clave_comercial,2,0)," ") | M6: =UPPER(IFERROR(VLOOKUP(J6,articulo:clave_comercial,5,0)," ")) | N6: =IFERROR(IF(VLOOKUP(J6,articulo:clave_comercial,8,0)=0," ",VLOOKUP(J6,articulo:clave_comercial,8,0))," ") | O6: =IFERROR(IF(VLOOKUP(J6,articulo:clave_comercial,9,0)=0," ",VLOOKUP(J6,articulo:clave_comercial,9,0))," ") | P6: =IFERROR(IF(M6="HOJA",(D6*F6)/MAX(ROUNDDOWN((N6/G6),0)*ROUNDDOWN((O6/H6),0),ROUNDDOWN((N6/H6),0)*ROUNDDOWN((O6/G6),0)),IF(M6="HOJA ",(D6*F6)/MAX(ROUNDDOWN((N6/G6),0)*ROUNDDOWN((O6/H6),0),ROUNDDOWN((N6/H6),0)*ROUNDDOWN((O6/G6),0)),IF(M6="M",G6,IF(AND(M6="PIEZA",G6<>0),(D6*F6)/ROUNDDOWN((N6/G6),0),IF(M6="PIEZA",(D6*F6),IF(M6="CAJA",(D6*F6),IF(M6="DM2",(D6*F6),IF(M6="FT",(D6*F6),IF(M6="JGO",(D6*F6),IF(M6="KG",(D6*F6),IF(M6="LB",(D6*F6),IF(M6="LT",(D6*F6),IF(M6="M2",(D6*F6),IF(M6="M3",(D6*F6),IF(M6="ROLLO",(D6*F6),IF(M6="SQYDS",(D6*F6),IF(M6="UD./SERV.",(D6*F6),IF(M6="YD",(D6*F6)," ")))))))))))))))))),"") | Q6: =IFERROR(IF(M6="HOJA",D6*F6*G6*H6*2*0.125,IF(AND(M6="PIEZA",H6=0),D6*F6*G6*VLOOKUP(J6,articulo:clave_comercial,10,0)*0.125,0))," ") -> 0 | S6: {=IFERROR(INDEX($J$3:$J$52,MATCH(0,INDEX(COUNTIF(S$2:$S5,$J$3:$J$52),0,0),0))," ")} | T6: {=IFERROR(INDEX($L$3:$L$52,MATCH(0,INDEX(COUNTIF($T$2:T5,$L$3:$L$52),0,0),0))," ")} | U6: =IFERROR(IF(AND(VLOOKUP(S6,$J$3:$Q$218,4,0)="KG",VLOOKUP(S6,$J$3:$Q$218,7,0)=0,VLOOKUP(S6,$J$3:$Q$218,8,0)=0),SUM($Q$3:$Q$218),SUMIF($J$3:$J$218,S6,$P$3:$P$218)),"") | W6: =IFERROR(IF(OR(M6="HOJA",M6="HOJA "),((MAX(ROUNDDOWN((0.915/G6),0)*ROUNDDOWN((2.44/H6),0),ROUNDDOWN((0.915/H6),0)*ROUNDDOWN((2.44/G6),0)))*G6*H6)/(0.915*2.44),""),"") | X6: =IFERROR(MAX(ROUNDDOWN((0.915/G6),0)*ROUNDDOWN((2.44/H6),0),ROUNDDOWN((0.915/H6),0)*ROUNDDOWN((2.44/G6),0)),"") | Y6: =IFERROR(IF(OR(M6="HOJA",M6="HOJA "),((MAX(ROUNDDOWN((0.915/G6),0)*ROUNDDOWN((3.05/H6),0),ROUNDDOWN((0.915/H6),0)*ROUNDDOWN((3.05/G6),0)))*G6*H6)/(0.915*3.05),""),"") | Z6: =IFERROR(MAX(ROUNDDOWN((0.915/G6),0)*ROUNDDOWN((3.05/H6),0),ROUNDDOWN((0.915/H6),0)*ROUNDDOWN((3.05/G6),0)),"") | AA6: =IFERROR(IF(OR(M6="HOJA",M6="HOJA "),((MAX(ROUNDDOWN((1.22/G6),0)*ROUNDDOWN((2.44/H6),0),ROUNDDOWN((1.22/H6),0)*ROUNDDOWN((2.44/G6),0)))*G6*H6)/(1.22*2.44),""),"") | AB6: =IFERROR(MAX(ROUNDDOWN((1.22/G6),0)*ROUNDDOWN((2.44/H6),0),ROUNDDOWN((1.22/H6),0)*ROUNDDOWN((2.44/G6),0)),"") | AC6: =IFERROR(IF(OR(M6="HOJA",M6="HOJA "),((MAX(ROUNDDOWN((1.22/G6),0)*ROUNDDOWN((3.05/H6),0),ROUNDDOWN((1.22/H6),0)*ROUNDDOWN((3.05/G6),0)))*G6*H6)/(1.22*3.05),""),"") | AD6: =IFERROR(MAX(ROUNDDOWN((1.22/G6),0)*ROUNDDOWN((3.05/H6),0),ROUNDDOWN((1.22/H6),0)*ROUNDDOWN((3.05/G6),0)),"")
L7: =IFERROR(VLOOKUP(J7,articulo:clave_comercial,2,0)," ") | M7: =UPPER(IFERROR(VLOOKUP(J7,articulo:clave_comercial,5,0)," ")) | N7: =IFERROR(IF(VLOOKUP(J7,articulo:clave_comercial,8,0)=0," ",VLOOKUP(J7,articulo:clave_comercial,8,0))," ") | O7: =IFERROR(IF(VLOOKUP(J7,articulo:clave_comercial,9,0)=0," ",VLOOKUP(J7,articulo:clave_comercial,9,0))," ") | P7: =IFERROR(IF(M7="HOJA",(D7*F7)/MAX(ROUNDDOWN((N7/G7),0)*ROUNDDOWN((O7/H7),0),ROUNDDOWN((N7/H7),0)*ROUNDDOWN((O7/G7),0)),IF(M7="HOJA ",(D7*F7)/MAX(ROUNDDOWN((N7/G7),0)*ROUNDDOWN((O7/H7),0),ROUNDDOWN((N7/H7),0)*ROUNDDOWN((O7/G7),0)),IF(M7="M",G7,IF(AND(M7="PIEZA",G7<>0),(D7*F7)/ROUNDDOWN((N7/G7),0),IF(M7="PIEZA",(D7*F7),IF(M7="CAJA",(D7*F7),IF(M7="DM2",(D7*F7),IF(M7="FT",(D7*F7),IF(M7="JGO",(D7*F7),IF(M7="KG",(D7*F7),IF(M7="LB",(D7*F7),IF(M7="LT",(D7*F7),IF(M7="M2",(D7*F7),IF(M7="M3",(D7*F7),IF(M7="ROLLO",(D7*F7),IF(M7="SQYDS",(D7*F7),IF(M7="UD./SERV.",(D7*F7),IF(M7="YD",(D7*F7)," ")))))))))))))))))),"") | Q7: =IFERROR(IF(M7="HOJA",D7*F7*G7*H7*2*0.125,IF(AND(M7="PIEZA",H7=0),D7*F7*G7*VLOOKUP(J7,articulo:clave_comercial,10,0)*0.125,0))," ") -> 0 | S7: {=IFERROR(INDEX($J$3:$J$52,MATCH(0,INDEX(COUNTIF(S$2:$S6,$J$3:$J$52),0,0),0))," ")} | T7: {=IFERROR(INDEX($L$3:$L$52,MATCH(0,INDEX(COUNTIF($T$2:T6,$L$3:$L$52),0,0),0))," ")} | U7: =IFERROR(IF(AND(VLOOKUP(S7,$J$3:$Q$218,4,0)="KG",VLOOKUP(S7,$J$3:$Q$218,7,0)=0,VLOOKUP(S7,$J$3:$Q$218,8,0)=0),SUM($Q$3:$Q$218),SUMIF($J$3:$J$218,S7,$P$3:$P$218)),"") | W7: =IFERROR(IF(OR(M7="HOJA",M7="HOJA "),((MAX(ROUNDDOWN((0.915/G7),0)*ROUNDDOWN((2.44/H7),0),ROUNDDOWN((0.915/H7),0)*ROUNDDOWN((2.44/G7),0)))*G7*H7)/(0.915*2.44),""),"") | X7: =IFERROR(MAX(ROUNDDOWN((0.915/G7),0)*ROUNDDOWN((2.44/H7),0),ROUNDDOWN((0.915/H7),0)*ROUNDDOWN((2.44/G7),0)),"") | Y7: =IFERROR(IF(OR(M7="HOJA",M7="HOJA "),((MAX(ROUNDDOWN((0.915/G7),0)*ROUNDDOWN((3.05/H7),0),ROUNDDOWN((0.915/H7),0)*ROUNDDOWN((3.05/G7),0)))*G7*H7)/(0.915*3.05),""),"") | Z7: =IFERROR(MAX(ROUNDDOWN((0.915/G7),0)*ROUNDDOWN((3.05/H7),0),ROUNDDOWN((0.915/H7),0)*ROUNDDOWN((3.05/G7),0)),"") | AA7: =IFERROR(IF(OR(M7="HOJA",M7="HOJA "),((MAX(ROUNDDOWN((1.22/G7),0)*ROUNDDOWN((2.44/H7),0),ROUNDDOWN((1.22/H7),0)*ROUNDDOWN((2.44/G7),0)))*G7*H7)/(1.22*2.44),""),"") | AB7: =IFERROR(MAX(ROUNDDOWN((1.22/G7),0)*ROUNDDOWN((2.44/H7),0),ROUNDDOWN((1.22/H7),0)*ROUNDDOWN((2.44/G7),0)),"") | AC7: =IFERROR(IF(OR(M7="HOJA",M7="HOJA "),((MAX(ROUNDDOWN((1.22/G7),0)*ROUNDDOWN((3.05/H7),0),ROUNDDOWN((1.22/H7),0)*ROUNDDOWN((3.05/G7),0)))*G7*H7)/(1.22*3.05),""),"") | AD7: =IFERROR(MAX(ROUNDDOWN((1.22/G7),0)*ROUNDDOWN((3.05/H7),0),ROUNDDOWN((1.22/H7),0)*ROUNDDOWN((3.05/G7),0)),"")
L8: =IFERROR(VLOOKUP(J8,articulo:clave_comercial,2,0)," ") | M8: =UPPER(IFERROR(VLOOKUP(J8,articulo:clave_comercial,5,0)," ")) | N8: =IFERROR(IF(VLOOKUP(J8,articulo:clave_comercial,8,0)=0," ",VLOOKUP(J8,articulo:clave_comercial,8,0))," ") | O8: =IFERROR(IF(VLOOKUP(J8,articulo:clave_comercial,9,0)=0," ",VLOOKUP(J8,articulo:clave_comercial,9,0))," ") | P8: =IFERROR(IF(M8="HOJA",(D8*F8)/MAX(ROUNDDOWN((N8/G8),0)*ROUNDDOWN((O8/H8),0),ROUNDDOWN((N8/H8),0)*ROUNDDOWN((O8/G8),0)),IF(M8="HOJA ",(D8*F8)/MAX(ROUNDDOWN((N8/G8),0)*ROUNDDOWN((O8/H8),0),ROUNDDOWN((N8/H8),0)*ROUNDDOWN((O8/G8),0)),IF(M8="M",G8,IF(AND(M8="PIEZA",G8<>0),(D8*F8)/ROUNDDOWN((N8/G8),0),IF(M8="PIEZA",(D8*F8),IF(M8="CAJA",(D8*F8),IF(M8="DM2",(D8*F8),IF(M8="FT",(D8*F8),IF(M8="JGO",(D8*F8),IF(M8="KG",(D8*F8),IF(M8="LB",(D8*F8),IF(M8="LT",(D8*F8),IF(M8="M2",(D8*F8),IF(M8="M3",(D8*F8),IF(M8="ROLLO",(D8*F8),IF(M8="SQYDS",(D8*F8),IF(M8="UD./SERV.",(D8*F8),IF(M8="YD",(D8*F8)," ")))))))))))))))))),"") | Q8: =IFERROR(IF(M8="HOJA",D8*F8*G8*H8*2*0.125,IF(AND(M8="PIEZA",H8=0),D8*F8*G8*VLOOKUP(J8,articulo:clave_comercial,10,0)*0.125,0))," ") -> 0 | S8: {=IFERROR(INDEX($J$3:$J$52,MATCH(0,INDEX(COUNTIF(S$2:$S7,$J$3:$J$52),0,0),0))," ")} | T8: {=IFERROR(INDEX($L$3:$L$52,MATCH(0,INDEX(COUNTIF($T$2:T7,$L$3:$L$52),0,0),0))," ")} | U8: =IFERROR(IF(AND(VLOOKUP(S8,$J$3:$Q$218,4,0)="KG",VLOOKUP(S8,$J$3:$Q$218,7,0)=0,VLOOKUP(S8,$J$3:$Q$218,8,0)=0),SUM($Q$3:$Q$218),SUMIF($J$3:$J$218,S8,$P$3:$P$218)),"") | W8: =IFERROR(IF(OR(M8="HOJA",M8="HOJA "),((MAX(ROUNDDOWN((0.915/G8),0)*ROUNDDOWN((2.44/H8),0),ROUNDDOWN((0.915/H8),0)*ROUNDDOWN((2.44/G8),0)))*G8*H8)/(0.915*2.44),""),"") | X8: =IFERROR(MAX(ROUNDDOWN((0.915/G8),0)*ROUNDDOWN((2.44/H8),0),ROUNDDOWN((0.915/H8),0)*ROUNDDOWN((2.44/G8),0)),"") | Y8: =IFERROR(IF(OR(M8="HOJA",M8="HOJA "),((MAX(ROUNDDOWN((0.915/G8),0)*ROUNDDOWN((3.05/H8),0),ROUNDDOWN((0.915/H8),0)*ROUNDDOWN((3.05/G8),0)))*G8*H8)/(0.915*3.05),""),"") | Z8: =IFERROR(MAX(ROUNDDOWN((0.915/G8),0)*ROUNDDOWN((3.05/H8),0),ROUNDDOWN((0.915/H8),0)*ROUNDDOWN((3.05/G8),0)),"") | AA8: =IFERROR(IF(OR(M8="HOJA",M8="HOJA "),((MAX(ROUNDDOWN((1.22/G8),0)*ROUNDDOWN((2.44/H8),0),ROUNDDOWN((1.22/H8),0)*ROUNDDOWN((2.44/G8),0)))*G8*H8)/(1.22*2.44),""),"") | AB8: =IFERROR(MAX(ROUNDDOWN((1.22/G8),0)*ROUNDDOWN((2.44/H8),0),ROUNDDOWN((1.22/H8),0)*ROUNDDOWN((2.44/G8),0)),"") | AC8: =IFERROR(IF(OR(M8="HOJA",M8="HOJA "),((MAX(ROUNDDOWN((1.22/G8),0)*ROUNDDOWN((3.05/H8),0),ROUNDDOWN((1.22/H8),0)*ROUNDDOWN((3.05/G8),0)))*G8*H8)/(1.22*3.05),""),"") | AD8: =IFERROR(MAX(ROUNDDOWN((1.22/G8),0)*ROUNDDOWN((3.05/H8),0),ROUNDDOWN((1.22/H8),0)*ROUNDDOWN((3.05/G8),0)),"")
A9: 2 | L9: =IFERROR(VLOOKUP(J9,articulo:clave_comercial,2,0)," ") | M9: =UPPER(IFERROR(VLOOKUP(J9,articulo:clave_comercial,5,0)," ")) | N9: =IFERROR(IF(VLOOKUP(J9,articulo:clave_comercial,8,0)=0," ",VLOOKUP(J9,articulo:clave_comercial,8,0))," ") | O9: =IFERROR(IF(VLOOKUP(J9,articulo:clave_comercial,9,0)=0," ",VLOOKUP(J9,articulo:clave_comercial,9,0))," ") | P9: =IFERROR(IF(M9="HOJA",(D9*F9)/MAX(ROUNDDOWN((N9/G9),0)*ROUNDDOWN((O9/H9),0),ROUNDDOWN((N9/H9),0)*ROUNDDOWN((O9/G9),0)),IF(M9="HOJA ",(D9*F9)/MAX(ROUNDDOWN((N9/G9),0)*ROUNDDOWN((O9/H9),0),ROUNDDOWN((N9/H9),0)*ROUNDDOWN((O9/G9),0)),IF(M9="M",G9,IF(AND(M9="PIEZA",G9<>0),(D9*F9)/ROUNDDOWN((N9/G9),0),IF(M9="PIEZA",(D9*F9),IF(M9="CAJA",(D9*F9),IF(M9="DM2",(D9*F9),IF(M9="FT",(D9*F9),IF(M9="JGO",(D9*F9),IF(M9="KG",(D9*F9),IF(M9="LB",(D9*F9),IF(M9="LT",(D9*F9),IF(M9="M2",(D9*F9),IF(M9="M3",(D9*F9),IF(M9="ROLLO",(D9*F9),IF(M9="SQYDS",(D9*F9),IF(M9="UD./SERV.",(D9*F9),IF(M9="YD",(D9*F9)," ")))))))))))))))))),"") | Q9: =IFERROR(IF(M9="HOJA",D9*F9*G9*H9*2*0.125,IF(AND(M9="PIEZA",H9=0),D9*F9*G9*VLOOKUP(J9,articulo:clave_comercial,10,0)*0.125,0))," ") -> 0 | S9: {=IFERROR(INDEX($J$3:$J$52,MATCH(0,INDEX(COUNTIF(S$2:$S8,$J$3:$J$52),0,0),0))," ")} | T9: {=IFERROR(INDEX($L$3:$L$52,MATCH(0,INDEX(COUNTIF($T$2:T8,$L$3:$L$52),0,0),0))," ")} | U9: =IFERROR(IF(AND(VLOOKUP(S9,$J$3:$Q$218,4,0)="KG",VLOOKUP(S9,$J$3:$Q$218,7,0)=0,VLOOKUP(S9,$J$3:$Q$218,8,0)=0),SUM($Q$3:$Q$218),SUMIF($J$3:$J$218,S9,$P$3:$P$218)),"") | W9: =IFERROR(IF(OR(M9="HOJA",M9="HOJA "),((MAX(ROUNDDOWN((0.915/G9),0)*ROUNDDOWN((2.44/H9),0),ROUNDDOWN((0.915/H9),0)*ROUNDDOWN((2.44/G9),0)))*G9*H9)/(0.915*2.44),""),"") | X9: =IFERROR(MAX(ROUNDDOWN((0.915/G9),0)*ROUNDDOWN((2.44/H9),0),ROUNDDOWN((0.915/H9),0)*ROUNDDOWN((2.44/G9),0)),"") | Y9: =IFERROR(IF(OR(M9="HOJA",M9="HOJA "),((MAX(ROUNDDOWN((0.915/G9),0)*ROUNDDOWN((3.05/H9),0),ROUNDDOWN((0.915/H9),0)*ROUNDDOWN((3.05/G9),0)))*G9*H9)/(0.915*3.05),""),"") | Z9: =IFERROR(MAX(ROUNDDOWN((0.915/G9),0)*ROUNDDOWN((3.05/H9),0),ROUNDDOWN((0.915/H9),0)*ROUNDDOWN((3.05/G9),0)),"") | AA9: =IFERROR(IF(OR(M9="HOJA",M9="HOJA "),((MAX(ROUNDDOWN((1.22/G9),0)*ROUNDDOWN((2.44/H9),0),ROUNDDOWN((1.22/H9),0)*ROUNDDOWN((2.44/G9),0)))*G9*H9)/(1.22*2.44),""),"") | AB9: =IFERROR(MAX(ROUNDDOWN((1.22/G9),0)*ROUNDDOWN((2.44/H9),0),ROUNDDOWN((1.22/H9),0)*ROUNDDOWN((2.44/G9),0)),"") | AC9: =IFERROR(IF(OR(M9="HOJA",M9="HOJA "),((MAX(ROUNDDOWN((1.22/G9),0)*ROUNDDOWN((3.05/H9),0),ROUNDDOWN((1.22/H9),0)*ROUNDDOWN((3.05/G9),0)))*G9*H9)/(1.22*3.05),""),"") | AD9: =IFERROR(MAX(ROUNDDOWN((1.22/G9),0)*ROUNDDOWN((3.05/H9),0),ROUNDDOWN((1.22/H9),0)*ROUNDDOWN((3.05/G9),0)),"")
